Workbook

Sheet 설정값
A1: 설정값 (전체 시트가 참조하는 조정 레버)
A2: 파란 글씨 = 직접 바꾸는 입력값, 검은 글씨 = 수식, 노란 칸 = 요청사항의 NN 값. 모든 수치는 기획 초안 가정값(출처: 기획안 v0.1).
A3: 항목 | B3: 값 | C3: 단위 | D3: 설명 | E3: 키
A4: 미매칭 AI 전환 대기 (NN초) | B4: 30 | C4: 초 | D4: 랭킹전 사람 탐색 후 AI 랭킹전으로 전환하는 시점 | E4: ai_fallback_sec
A5: AI 랭킹전 승점 감산율 (NN%) | B5: 0.4 | C5: % | D5: AI전 RP = 사람 대전 RP × (1 − 이 값). 승리·패배 모두 | E5: ai_rp_penalty_pct
A6: AI 랭킹전 하루 승점 반영 판수 | B6: 5 | C6: 판 | D6: 초과분은 판 보상만, RP 0 | E6: ai_daily_rp_games
A7: AI 대체 비활성 시작 티어 순번 | B7: 13 | C7: 단계 순번 | D7: 13 = 다이아 III부터 AI 대체 없음 (랭크_승점 시트 순번) | E7: ai_off_from_tier_no
A8: 턴 선택 시간 | B8: 20 | C8: 초 | D8: 양측 확정 시 즉시 공개 | E8: turn_select_sec
A9: 타임뱅크 (판당 1회) | B9: 15 | C9: 초 | E9: timebank_sec
A10: 최대 턴 | B10: 10 | C10: 턴 | E10: max_turn
A11: 폭주 시작 턴 | B11: 7 | C11: 턴 | E11: rush_start_turn
A12: 폭주 턴당 피해 증가 | B12: 0.25 | C12: % | D12: 7턴 +25%, 8턴 +50% ... 누적 | E12: rush_dmg_step
A13: 폭주 중 회복 감소 | B13: 0.5 | C13: % | E13: rush_heal_cut
A14: 기본 승리 RP | B14: 25 | C14: RP | E14: win_rp_base
A15: 기본 패배 RP | B15: 20 | C15: RP | D15: 양수로 입력, 차감값 | E15: loss_rp_base
A16: MMR 보정 최대 | B16: 8 | C16: RP | D16: MMR이 단계 기준보다 높으면 승리 +, 패배 − | E16: mmr_adj_max
A17: MMR 보정 계수 | B17: 20 | C17: MMR/RP | D17: MMR 20 차이당 RP 1 | E17: mmr_adj_per
A18: 연승 보너스 시작 (n연승째) | B18: 3 | C18: 연승 | E18: streak_start
A19: 연승 보너스 RP (단계당) | B19: 5 | C19: RP | E19: streak_rp_step
A20: 연승 보너스 최대 | B20: 10 | C20: RP | E20: streak_rp_max
A21: 이탈 추가 RP 감점 | B21: 10 | C21: RP | D21: 패배 RP에 더해 차감 | E21: leave_rp_penalty
A22: 닷지 RP 감점 | B22: 5 | C22: RP | D22: 밴픽 중 이탈 | E22: dodge_rp_penalty
A23: 시즌 리셋 하락 단계 | B23: 4 | C23: 단계 | E23: season_reset_tiers
A24: 시즌 초반 승리 배율 | B24: 1.5 | C24: 배 | D24: 지난 시즌 최고 단계 재도달 전까지 | E24: season_early_win_mult
A25: 단계당 RP | B25: 100 | C25: RP | E25: rp_per_tier
A26: 치명 배율 | B26: 1.5 | C26: 배 | E26: crit_mult
A27: 스탯 예산 목표 | B27: 280 | C27: 점 | D27: 모든 캐릭터 공통 | E27: stat_budget_target
A28: 스탯 예산 허용 편차 | B28: 0.03 | C28: % | E28: stat_budget_tol
A29: 재접속 유예 | B29: 60 | C29: 초 | E29: reconnect_grace_sec
A30: 레전드 기준 (마스터 상위 N%) | B30: 0.1 | C30: % | D30: 마스터 중 시즌 RP 상위 N%가 레전드(상세 08) | E30: legend_top_pct
A31: 레전드 최대 인원 | B31: 100 | C31: 명 | D31: 상위 N%가 이 수를 넘으면 이 수까지만 | E31: legend_cap
A32: 승급 시 AI 판 RP 인정 | B32: 1 | C32: 1=켬 0=끔 | D32: 승급전에서 AI 랭킹전 RP를 인정할지(기본 켬) | E32: promo_ai_counts
A33: 밴 선택 시간 | B33: 10 | C33: 초 | D33: 밴 단계, 양측 동시(총괄 7장) | E33: ban_sec
A34: 픽 선택 시간 | B34: 15 | C34: 초 | D34: 픽 단계, 동시·비공개(총괄 7장) | E34: pick_sec
A35: 스펠·덱 선택 시간 | B35: 15 | C35: 초 | D35: 상대 공개 후 스펠 2종과 덱 프리셋을 고르는 시간(총괄 7장) | E35: loadout_sec
A36: 숨은 MMR 갱신 폭(K) | B36: 32 | C36: MMR | D36: 판 결과마다 Elo 방식으로 갱신, 시작값은 시트 `랭크_승점` 기준 MMR 시작 | E36: mmr_k
A37: 대체 AI 차선 확률(브론즈~실버) | B37: 0.15 | C37: % | D37: 랭킹전 대체 AI가 1등 대신 차선을 고를 확률(상세 03) | E37: ai_subopt_bronze_silver
A38: 대체 AI 차선 확률(골드~플래티넘) | B38: 0.05 | C38: % | D38: 같은 항목, 매주 승률 50~55%를 보고 ±3%p 이내로 조정(상세 03) | E38: ai_subopt_gold_plat
A40: 키(영문)는 서버·클라이언트가 값을 읽는 이름이다. 등록 후 변경하지 않는다.

Sheet 시간예산
A1: 판당 시간 예산 (목표: 한 판 3~5분)
A2: 시나리오별 입력(파란 글씨)을 바꾸면 전투·전체 시간이 다시 계산된다.
A3: 시나리오 | B3: 매칭 대기(초) | C3: 밴(초) | D3: 픽(초) | E3: 스펠·덱(초) | F3: 공개 연출(초) | G3: 턴 수 | H3: 턴당 선택(초) | I3: 턴당 공개 연출(초) | J3: 타임뱅크 사용(초) | K3: 결과 화면(초) | L3: 전투(초) | M3: 전투(분) | N3: 한 판 전체(초) | O3: 한 판 전체(분) | P3: 3~5분 안?
A4: 빠른 판 | B4: 10 | C4: 6 | D4: 8 | E4: 8 | F4: 5 | G4: 5 | H4: 10 | I4: 6 | J4: 0 | K4: 15 | L4: =G4*(H4+I4)+J4 -> 80 | M4: =L4/60 -> 1.3333333 | N4: =B4+C4+D4+E4+F4+L4+K4 -> 132 | O4: =N4/60 -> 2.2 | P4: =IF(AND(O4>=3,O4<=5),"예",IF(O4<3,"짧음","김")) -> 짧음
A5: 평균 판 | B5: 20 | C5: 10 | D5: 15 | E5: 15 | F5: 5 | G5: 7 | H5: 15 | I5: 7 | J5: 0 | K5: 15 | L5: =G5*(H5+I5)+J5 -> 154 | M5: =L5/60 -> 2.5666667 | N5: =B5+C5+D5+E5+F5+L5+K5 -> 234 | O5: =N5/60 -> 3.9 | P5: =IF(AND(O5>=3,O5<=5),"예",IF(O5<3,"짧음","김")) -> 예
A6: 긴 판 | B6: 30 | C6: 10 | D6: 15 | E6: 15 | F6: 5 | G6: 9 | H6: 18 | I6: 8 | J6: 15 | K6: 15 | L6: =G6*(H6+I6)+J6 -> 249 | M6: =L6/60 -> 4.15 | N6: =B6+C6+D6+E6+F6+L6+K6 -> 339 | O6: =N6/60 -> 5.65 | P6: =IF(AND(O6>=3,O6<=5),"예",IF(O6<3,"짧음","김")) -> 김
A7: 최악 판(모든 상한) | B7: =설정값!$B$4 -> 30 | C7: 10 | D7: 15 | E7: 15 | F7: 5 | G7: =설정값!$B$10 -> 10 | H7: =설정값!$B$8 -> 20 | I7: 8 | J7: =2*설정값!$B$9 -> 30 | K7: 15 | L7: =G7*(H7+I7)+J7 -> 310 | M7: =L7/60 -> 5.1666667 | N7: =B7+C7+D7+E7+F7+L7+K7 -> 400 | O7: =N7/60 -> 6.6666667 | P7: =IF(AND(O7>=3,O7<=5),"예",IF(O7<3,"짧음","김")) -> 김
A9: 최악 판 전투 시간(타임뱅크 제외, 분) | B9: =(L7-J7)/60 -> 4.6666667
A10: 메모: 최악 판은 설계상 상한(10턴·매 턴 시간 초과)이라 5분을 넘는다. 운영 지표는 '평균 판'과 판 길이 분포의 90% 지점으로 본다.

Sheet 캐릭터
A1: 캐릭터 스탯과 스탯 예산
A2: 예산 = HP×w1 + ATK×w2 + DEF×w3 + SPD×w4 + CRIT×w5. 등급이 달라도 예산은 같게(±허용 편차). SPD 가중치는 전투 가치(연출 순서·동률)에 맞춰 0.1로 낮췄다(2026-10-24, 목표 280).
A3: 가중치 | F3: 0.1 | G3: 1 | H3: 1.25 | I3: 0.1 | J3: 2
A4: 캐릭터 | B4: 직업 | C4: 등급 | D4: 역할 | E4: 제공 방식 | F4: HP | G4: ATK | H4: DEF | I4: SPD | J4: CRIT(%) | K4: 스탯 예산 | L4: 목표 대비 | M4: 판정 | N4: 패시브 | O4: 액티브 | P4: 진영 | Q4: ID | R4: 패시브 수치 | S4: 액티브 수치
A5: 아우렐 | B5: 태양 기사 | C5: 일반 | D5: 탱커 | E5: 본편 포함 | F5: 1200 | G5: 85 | H5: 45 | I5: 85 | J5: 5 | K5: =F5*$F$3+G5*$G$3+H5*$H$3+I5*$I$3+J5*$J$3 -> 279.75 | L5: =K5/설정값!$B$27-1 -> -0.00089285714 | M5: =IF(ABS(L5)<=설정값!$B$28,"OK",IF(L5>0,"초과","미달")) -> OK | N5: 태양 방패: 방어 카드 실드 +20%, 턴 종료 시 남은 실드 50% 이월 | O5: 일륜 반격: 보유 실드의 150%를 피해로 전환, 실드 소멸 | P5: 불 | Q5: AU | R5: passive_shield_bonus=0.2;passive_carry=0.5 | S5: active_mult=1.5
A6: 피로스 | B6: 광전사 | C6: 희귀 | D6: 브루저 | E6: 본편 포함 | F6: 1100 | G6: 108 | H6: 33 | I6: 80 | J6: 10 | K6: =F6*$F$3+G6*$G$3+H6*$H$3+I6*$I$3+J6*$J$3 -> 287.25 | L6: =K6/설정값!$B$27-1 -> 0.025892857 | M6: =IF(ABS(L6)<=설정값!$B$28,"OK",IF(L6>0,"초과","미달")) -> OK | N6: 타오르는 피: 잃은 HP 10%당 ATK +3% | O6: 업화: 2턴간 공격 카드 피해 ×1.5, 받는 피해 +15% | P6: 불 | Q6: PY | R6: passive_atk_per10=0.03 | S6: active_turns=2;active_taken_up=0.15;active_hits=1;active_hit_mult=1.5
A7: 이그니스 | B7: 불꽃 검사 | C7: 전설 | D7: 견제 | E7: 본편 포함 | F7: 950 | G7: 100 | H7: 40 | I7: 105 | J7: 15 | K7: =F7*$F$3+G7*$G$3+H7*$H$3+I7*$I$3+J7*$J$3 -> 285.5 | L7: =K7/설정값!$B$27-1 -> 0.019642857 | M7: =IF(ABS(L7)<=설정값!$B$28,"OK",IF(L7>0,"초과","미달")) -> OK | N7: 불씨: 공격 적중 시 25% 작열 1스택(2턴, 턴당 최대 HP 3%, 최대 3스택) | O7: 대화재: 상대의 남은 작열 피해를 2배로 즉시 터뜨림 | P7: 불 | Q7: IG | R7: passive_chance=0.25 | S7: active_mult=2
A8: 셀레네 | B8: 달빛 사제 | C8: 일반 | D8: 유지 | E8: 본편 포함 | F8: 1050 | G8: 90 | H8: 50 | I8: 95 | J8: 5 | K8: =F8*$F$3+G8*$G$3+H8*$H$3+I8*$I$3+J8*$J$3 -> 277 | L8: =K8/설정값!$B$27-1 -> -0.010714286 | M8: =IF(ABS(L8)<=설정값!$B$28,"OK",IF(L8>0,"초과","미달")) -> OK | N8: 월광: 턴 종료 시 최대 HP 3% 회복, 넘친 회복은 실드로(최대 HP 10%) | O8: 만월 역행: HP를 2턴 전 시작 시점으로 되돌림 | P8: 물 | Q8: SE | R8: passive_regen=0.03;passive_shield_cap=0.1 | S8: active_lookback=2
A9: 실피 | B9: 바람 사수 | C9: 희귀 | D9: 템포 | E9: 본편 포함 | F9: 1000 | G9: 104 | H9: 35 | I9: 130 | J9: 10 | K9: =F9*$F$3+G9*$G$3+H9*$H$3+I9*$I$3+J9*$J$3 -> 280.75 | L9: =K9/설정값!$B$27-1 -> 0.0026785714 | M9: =IF(ABS(L9)<=설정값!$B$28,"OK",IF(L9>0,"초과","미달")) -> OK | N9: 순풍: 매 턴 처음 내는 1E 카드는 에너지 0 | O9: 회오리: 상대 손패를 덱에 섞고 같은 장수만큼 다시 뽑게 함, 상대 다음 턴 에너지 이월 0 | P9: 바람 | Q9: SL | R9: passive_free_cards=1 | S9: active_no_carry_turns=1
A10: 테티스 | B10: 조수의 창기사 | C10: 영웅 | D10: 리듬 브루저 | E10: 본편 포함 | F10: 1050 | G10: 100 | H10: 45 | I10: 90 | J10: 5 | K10: =F10*$F$3+G10*$G$3+H10*$H$3+I10*$I$3+J10*$J$3 -> 280.25 | L10: =K10/설정값!$B$27-1 -> 0.00089285714 | M10: =IF(ABS(L10)<=설정값!$B$28,"OK",IF(L10>0,"초과","미달")) -> OK | N10: 조류: 홀수 턴 공격 피해 +20%, 짝수 턴 받는 피해 −20% | O10: 대조류: 2턴간 밀물·썰물 효과 동시 적용 | P10: 물 | Q10: TE | R10: passive_flood=0.2;passive_ebb=0.2 | S10: active_turns=2
A11: 움브라 | B11: 그림자 암살자 | C11: 일반 | D11: 딜러 | E11: 본편 포함 | F11: 900 | G11: 115 | H11: 32 | I11: 110 | J11: 15 | K11: =F11*$F$3+G11*$G$3+H11*$H$3+I11*$I$3+J11*$J$3 -> 286 | L11: =K11/설정값!$B$27-1 -> 0.021428571 | M11: =IF(ABS(L11)<=설정값!$B$28,"OK",IF(L11>0,"초과","미달")) -> OK | N11: 어둠의 칼날: 상대 HP 50% 이하일 때 치명 +15%p | O11: 처형: 상대가 잃은 HP의 35% 피해, 방어력·실드 무시 | P11: 바람 | Q11: UM | R11: passive_crit_bonus=15;passive_hp_below=0.5 | S11: active_pct=0.35
A12: 실렌티아 | B12: 침묵의 수녀 | C12: 희귀 | D12: 컨트롤 | E12: 본편 포함 | F12: 980 | G12: 105 | H12: 37 | I12: 115 | J12: 10 | K12: =F12*$F$3+G12*$G$3+H12*$H$3+I12*$I$3+J12*$J$3 -> 280.75 | L12: =K12/설정값!$B$27-1 -> 0.0026785714 | M12: =IF(ABS(L12)<=설정값!$B$28,"OK",IF(L12>0,"초과","미달")) -> OK | N12: 고요: 침묵 카드 사용 시 1장 드로우 | O12: 망각의 밤: 상대 다음 턴 에너지 −1, 손패 1장 봉인 | P12: 바람 | Q12: SI | R12: passive_draw=1 | S12: active_energy_down=1;active_seal=1
A13: 모르테 | B13: 망령 기사 | C13: 영웅 | D13: 탱커 | E13: 본편 포함 | F13: 1220 | G13: 80 | H13: 50 | I13: 75 | J13: 5 | K13: =F13*$F$3+G13*$G$3+H13*$H$3+I13*$I$3+J13*$J$3 -> 282 | L13: =K13/설정값!$B$27-1 -> 0.0071428571 | M13: =IF(ABS(L13)<=설정값!$B$28,"OK",IF(L13>0,"초과","미달")) -> OK | N13: 죽음의 그림자: 상대가 약화 상태면 받는 피해 −15% | O13: 영혼 수확: 상대에게 건 디버프 횟수(최대 5)×상대 최대 HP 6% 피해 + 그만큼 회복 | P13: 물 | Q13: MO | R13: passive_reduce=0.15 | S13: active_per_debuff=0.06;active_max_debuffs=5
A15: SPD: 같은 처리 단계 안에서 연출 순서. 판정은 단계 단위로 동시. 액티브 게이지: 턴 시작 +15, 쓴 에너지 1당 +8.
A16: ID: 영문 대문자 2~3자, 중복 불가, 등록 후 변경 불가(전용카드 ID = 캐릭터 ID + 2자리 순번, 상세 14). 제공 방식: 출시 9명은 모두 본편 포함, 출시 후 추가 캐릭터는 "유료 추가".
A17: 패시브 수치·액티브 수치: 엔진이 읽는 스킬 수치(키=값;키=값). 문구와 다르면 이 열이 기준이다(상세 14).

Sheet 전투카드
A1: 전투카드 (공용 16 + 전용 18)
A2: 기대 피해는 기준 공격자/방어자 대비(버프·치명·폭주 제외). 에너지당 피해로 효율을 비교한다.
A3: 기준 ATK | B3: 100 | C3: 기준 DEF | D3: 40
A4: ID | B4: 카드명 | C4: 종류 | D4: 처리 단계 | E4: 공용/전용 | F4: 비용(E) | G4: 계수 | H4: 타수 | I4: 관통 | J4: 효과 | K4: 기대 피해 | L4: 에너지당 피해
A5: C01 | B5: 베기 | C5: 공격 | D5: 4 | E5: 공용 | F5: 1 | G5: 1 | H5: 1 | I5: 0 | J5: ATK×1.0 | K5: =IF(C5="공격",$B$3*G5*H5*100/(100+$D$3*(1-I5)),"") -> 71.428571 | L5: =IF(C5="공격",K5/F5,"") -> 71.428571
A6: C02 | B6: 강타 | C6: 공격 | D6: 4 | E6: 공용 | F6: 2 | G6: 1.8 | H6: 1 | I6: 0 | J6: ATK×1.8 | K6: =IF(C6="공격",$B$3*G6*H6*100/(100+$D$3*(1-I6)),"") -> 128.57143 | L6: =IF(C6="공격",K6/F6,"") -> 64.285714
A7: C03 | B7: 연속 찌르기 | C7: 공격 | D7: 4 | E7: 공용 | F7: 2 | G7: 0.6 | H7: 3 | I7: 0 | J7: ATK×0.6 3회. 타격마다 실드 차감 | K7: =IF(C7="공격",$B$3*G7*H7*100/(100+$D$3*(1-I7)),"") -> 128.57143 | L7: =IF(C7="공격",K7/F7,"") -> 64.285714
A8: C04 | B8: 관통 일격 | C8: 공격 | D8: 4 | E8: 공용 | F8: 3 | G8: 1.5 | H8: 1 | I8: 0.5 | J8: ATK×1.5, 방어력 50% 무시 | K8: =IF(C8="공격",$B$3*G8*H8*100/(100+$D$3*(1-I8)),"") -> 125 | L8: =IF(C8="공격",K8/F8,"") -> 41.666667
A9: C05 | B9: 막기 | C9: 방어 | D9: 1 | E9: 공용 | F9: 1 | G9: 2 | J9: 실드 DEF×2.0 (이번 턴) | K9: =IF(C9="공격",$B$3*G9*H9*100/(100+$D$3*(1-I9)),"") | L9: =IF(C9="공격",K9/F9,"")
A10: C06 | B10: 철벽 | C10: 방어 | D10: 1 | E10: 공용 | F10: 2 | G10: 3.5 | J10: 실드 DEF×3.5 (이번 턴) | K10: =IF(C10="공격",$B$3*G10*H10*100/(100+$D$3*(1-I10)),"") | L10: =IF(C10="공격",K10/F10,"")
A11: C07 | B11: 받아치기 | C11: 반격 | D11: 1 | E11: 공용 | F11: 2 | G11: 0.8 | J11: 상대 공격 카드 1장 무효 + ATK×0.8 반격 | K11: =IF(C11="공격",$B$3*G11*H11*100/(100+$D$3*(1-I11)),"") | L11: =IF(C11="공격",K11/F11,"")
A12: C08 | B12: 봉인 | C12: 침묵 | D12: 2 | E12: 공용 | F12: 2 | J12: 상대 이번 턴 스킬·액티브 무효, 다음 턴 액티브 봉인 | K12: =IF(C12="공격",$B$3*G12*H12*100/(100+$D$3*(1-I12)),"") | L12: =IF(C12="공격",K12/F12,"")
A13: C09 | B13: 쉿 | C13: 침묵 | D13: 2 | E13: 공용 | F13: 1 | J13: 상대 다음 턴 스킬 봉쇄(이번 턴 효과 없음) | K13: =IF(C13="공격",$B$3*G13*H13*100/(100+$D$3*(1-I13)),"") | L13: =IF(C13="공격",K13/F13,"")
A14: C10 | B14: 정신 집중 | C14: 면역 | D14: 1 | E14: 공용 | F14: 1 | J14: 이번 턴 + 다음 턴 디버프 면역 | K14: =IF(C14="공격",$B$3*G14*H14*100/(100+$D$3*(1-I14)),"") | L14: =IF(C14="공격",K14/F14,"")
A15: C11 | B15: 신성 결계 | C15: 면역 | D15: 1 | E15: 공용 | F15: 2 | G15: 1 | J15: 이번 턴 디버프 면역 + 디버프 해제 + 실드 DEF×1.0 | K15: =IF(C15="공격",$B$3*G15*H15*100/(100+$D$3*(1-I15)),"") | L15: =IF(C15="공격",K15/F15,"")
A16: C12 | B16: 약화 | C16: 방해 | D16: 2 | E16: 공용 | F16: 1 | G16: 0.2 | J16: 상대 다음 턴 ATK −20% | K16: =IF(C16="공격",$B$3*G16*H16*100/(100+$D$3*(1-I16)),"") | L16: =IF(C16="공격",K16/F16,"")
A17: C13 | B17: 응급 처치 | C17: 스킬 | D17: 3 | E17: 공용 | F17: 2 | G17: 0.12 | J17: 최대 HP 12% 회복 | K17: =IF(C17="공격",$B$3*G17*H17*100/(100+$D$3*(1-I17)),"") | L17: =IF(C17="공격",K17/F17,"")
A18: C14 | B18: 집중 | C18: 스킬 | D18: 3 | E18: 공용 | F18: 1 | G18: 25 | J18: 스킬 게이지 +25 | K18: =IF(C18="공격",$B$3*G18*H18*100/(100+$D$3*(1-I18)),"") | L18: =IF(C18="공격",K18/F18,"")
A19: C15 | B19: 전술 드로우 | C19: 스킬 | D19: 3 | E19: 공용 | F19: 1 | G19: 2 | J19: 카드 2장 드로우 | K19: =IF(C19="공격",$B$3*G19*H19*100/(100+$D$3*(1-I19)),"") | L19: =IF(C19="공격",K19/F19,"")
A20: C16 | B20: 분노 | C20: 스킬 | D20: 3 | E20: 공용 | F20: 1 | G20: 0.3 | J20: 공격 강화: 이번 턴 공격 피해 +30% | K20: =IF(C20="공격",$B$3*G20*H20*100/(100+$D$3*(1-I20)),"") | L20: =IF(C20="공격",K20/F20,"")
A21: AU01 | B21: 일출의 방패 | C21: 방어 | D21: 1 | E21: 아우렐 | F21: 2 | G21: 2.5 | J21: 실드 DEF×2.5, 이 실드는 다음 턴 100% 이월 | K21: =IF(C21="공격",$B$3*G21*H21*100/(100+$D$3*(1-I21)),"") | L21: =IF(C21="공격",K21/F21,"")
A22: AU02 | B22: 정오의 결의 | C22: 스킬 | D22: 3 | E22: 아우렐 | F22: 1 | G22: 0.3 | J22: 현재 실드 +30%, 게이지 +20 | K22: =IF(C22="공격",$B$3*G22*H22*100/(100+$D$3*(1-I22)),"") | L22: =IF(C22="공격",K22/F22,"")
A23: PY01 | B23: 불꽃 일격 | C23: 공격 | D23: 4 | E23: 피로스 | F23: 2 | G23: 2 | H23: 1 | I23: 0 | J23: ATK×2.0, 자신 최대 HP 5% 소모 | K23: =IF(C23="공격",$B$3*G23*H23*100/(100+$D$3*(1-I23)),"") -> 142.85714 | L23: =IF(C23="공격",K23/F23,"") -> 71.428571
A24: PY02 | B24: 연소 | C24: 스킬 | D24: 3 | E24: 피로스 | F24: 1 | G24: 35 | J24: 자신 최대 HP 8% 소모, 게이지 +35 | K24: =IF(C24="공격",$B$3*G24*H24*100/(100+$D$3*(1-I24)),"") | L24: =IF(C24="공격",K24/F24,"")
A25: IG01 | B25: 화염 결계 | C25: 반격 | D25: 1 | E25: 이그니스 | F25: 2 | G25: 2 | J25: 상대 공격 카드 1장 무효 + 작열 2스택 | K25: =IF(C25="공격",$B$3*G25*H25*100/(100+$D$3*(1-I25)),"") | L25: =IF(C25="공격",K25/F25,"")
A26: IG02 | B26: 불티 세례 | C26: 공격 | D26: 4 | E26: 이그니스 | F26: 2 | G26: 0.5 | H26: 3 | I26: 0 | J26: ATK×0.5 3회, HP 피해가 들어가면 작열 1스택 | K26: =IF(C26="공격",$B$3*G26*H26*100/(100+$D$3*(1-I26)),"") -> 107.14286 | L26: =IF(C26="공격",K26/F26,"") -> 53.571429
A27: SE01 | B27: 달의 기도 | C27: 스킬 | D27: 3 | E27: 셀레네 | F27: 1 | G27: 0.5 | J27: 이번·다음 턴 회복량 +50%, 게이지 +15 | K27: =IF(C27="공격",$B$3*G27*H27*100/(100+$D$3*(1-I27)),"") | L27: =IF(C27="공격",K27/F27,"")
A28: SE02 | B28: 월광 일섬 | C28: 공격 | D28: 4 | E28: 셀레네 | F28: 2 | G28: 1.2 | H28: 1 | I28: 0 | J28: ATK×1.2, 준 HP 피해의 30% 회복 | K28: =IF(C28="공격",$B$3*G28*H28*100/(100+$D$3*(1-I28)),"") -> 85.714286 | L28: =IF(C28="공격",K28/F28,"") -> 42.857143
A29: SL01 | B29: 산들바람 | C29: 스킬 | D29: 3 | E29: 실피 | F29: 1 | G29: 1 | J29: 1장 드로우, 게이지 +20 | K29: =IF(C29="공격",$B$3*G29*H29*100/(100+$D$3*(1-I29)),"") | L29: =IF(C29="공격",K29/F29,"")
A30: SL02 | B30: 칼바람 | C30: 공격 | D30: 4 | E30: 실피 | F30: 1 | G30: 0.7 | H30: 1 | I30: 0 | J30: ATK×0.7, 이번 턴 내 SPD가 더 높으면 ×1.5 | K30: =IF(C30="공격",$B$3*G30*H30*100/(100+$D$3*(1-I30)),"") -> 50 | L30: =IF(C30="공격",K30/F30,"") -> 50
A31: TE01 | B31: 밀물 찌르기 | C31: 공격 | D31: 4 | E31: 테티스 | F31: 2 | G31: 1.3 | H31: 1 | I31: 0 | J31: ATK×1.3, 밀물(홀수) 턴이면 게이지 +20 | K31: =IF(C31="공격",$B$3*G31*H31*100/(100+$D$3*(1-I31)),"") -> 92.857143 | L31: =IF(C31="공격",K31/F31,"") -> 46.428571
A32: TE02 | B32: 썰물 방벽 | C32: 방어 | D32: 1 | E32: 테티스 | F32: 1 | G32: 1.5 | J32: 실드 DEF×1.5, 썰물(짝수) 턴이면 ×2 | K32: =IF(C32="공격",$B$3*G32*H32*100/(100+$D$3*(1-I32)),"") | L32: =IF(C32="공격",K32/F32,"")
A33: UM01 | B33: 그림자 표식 | C33: 방해 | D33: 2 | E33: 움브라 | F33: 1 | G33: 0.2 | J33: 표식: 2턴간 받는 치명 피해 +20%, 처형 계수 +10%p | K33: =IF(C33="공격",$B$3*G33*H33*100/(100+$D$3*(1-I33)),"") | L33: =IF(C33="공격",K33/F33,"")
A34: UM02 | B34: 그림자 걸음 | C34: 스킬 | D34: 3 | E34: 움브라 | F34: 1 | G34: 25 | J34: 다음 턴 SPD +30, 게이지 +25 | K34: =IF(C34="공격",$B$3*G34*H34*100/(100+$D$3*(1-I34)),"") | L34: =IF(C34="공격",K34/F34,"")
A35: SI01 | B35: 마나 붕괴 | C35: 침묵 | D35: 2 | E35: 실렌티아 | F35: 2 | G35: 30 | J35: 봉인 효과 + 상대 게이지 −30 | K35: =IF(C35="공격",$B$3*G35*H35*100/(100+$D$3*(1-I35)),"") | L35: =IF(C35="공격",K35/F35,"")
A36: SI02 | B36: 어둠 화살 | C36: 공격 | D36: 4 | E36: 실렌티아 | F36: 1 | G36: 0.9 | H36: 1 | I36: 0 | J36: ATK×0.9, 침묵 상태 상대에게 +50% | K36: =IF(C36="공격",$B$3*G36*H36*100/(100+$D$3*(1-I36)),"") -> 64.285714 | L36: =IF(C36="공격",K36/F36,"") -> 64.285714
A37: MO01 | B37: 저주의 손길 | C37: 방해 | D37: 2 | E37: 모르테 | F37: 1 | G37: 0.2 | J37: 상대 약화 2턴(ATK −20%) | K37: =IF(C37="공격",$B$3*G37*H37*100/(100+$D$3*(1-I37)),"") | L37: =IF(C37="공격",K37/F37,"")
A38: MO02 | B38: 망령 갑주 | C38: 방어 | D38: 1 | E38: 모르테 | F38: 2 | G38: 2 | J38: 실드 DEF×2.0, 약화 상태 상대에게 맞으면 실드 +50% | K38: =IF(C38="공격",$B$3*G38*H38*100/(100+$D$3*(1-I38)),"") | L38: =IF(C38="공격",K38/F38,"")
A40: 처리 단계: 0 스펠 → 1 보호(면역·방어·반격) → 2 방해(침묵·방해) → 3 스킬 → 4 공격 → 5 턴 종료. 계수 칸은 종류별 의미가 다름(실드 배수, 회복 비율, 게이지량 등). 이 번호는 총괄 6장의 처리 순서와 같다(0은 스펠 시트, 5는 카드가 없는 턴 종료 처리).
A42: 카드 종류 7종 (정식 목록)
...

Sheet 스펠
A1: 스펠 (8종 중 2종 선택, 방어·유틸만)
A2: 판당 최대 사용 횟수 = 1 + 내림((판 길이 − 최초 사용 턴) ÷ 쿨다운)
A3: 최초 사용 가능 턴 | C3: 2 | D3: 평균 판 턴 수 | F3: =시간예산!G5 -> 7
A4: 스펠 | B4: 효과 | C4: 효과값 | D4: 쿨다운(턴) | E4: 최대 턴 판 최대 사용 | F4: 평균 판 최대 사용 | G4: 메모 | H4: ID
A5: 수호 | B5: 이번 턴 받는 모든 피해 0(지속 피해 포함) | C5: 1 | D5: 5 | E5: =1+INT((설정값!$B$10-$C$3)/D5) -> 2 | F5: =1+INT(($F$3-$C$3)/D5) -> 2 | G5: 상대가 공격 안 하면 헛방 | H5: SP01
A6: 거울 | B6: 이번 턴 받는 직접 피해의 N% 반사(받는 피해 그대로) | C6: 0.5 | D6: 4 | E6: =1+INT((설정값!$B$10-$C$3)/D6) -> 3 | F6: =1+INT(($F$3-$C$3)/D6) -> 2 | G6: 반사 피해 재반사 없음 | H6: SP02
A7: 정화 | B7: 디버프 전부 해제 + 이번 턴 디버프 면역 | D7: 4 | E7: =1+INT((설정값!$B$10-$C$3)/D7) -> 3 | F7: =1+INT(($F$3-$C$3)/D7) -> 2 | G7: 침묵·작열 대응 | H7: SP03
A8: 회복 | B8: 최대 HP N% 회복(폭주 중 절반) | C8: 0.15 | D8: 5 | E8: =1+INT((설정값!$B$10-$C$3)/D8) -> 2 | F8: =1+INT(($F$3-$C$3)/D8) -> 2 | H8: SP04
A9: 봉쇄 | B9: 이번 턴 상대 스펠 효과 무효 | D9: 5 | E9: =1+INT((설정값!$B$10-$C$3)/D9) -> 2 | F9: =1+INT(($F$3-$C$3)/D9) -> 2 | G9: 상대가 스펠을 안 쓰면 헛방, 양측 봉쇄면 상쇄 | H9: SP05
A10: 충전 | B10: 이번 턴 에너지 +N | C10: 2 | D10: 5 | E10: =1+INT((설정값!$B$10-$C$3)/D10) -> 2 | F10: =1+INT(($F$3-$C$3)/D10) -> 2 | G10: 큰 카드 콤보 | H10: SP06
A11: 통찰 | B11: 즉시 N장 드로우 + 상대 손패 1장 공개 | C11: 2 | D11: 4 | E11: =1+INT((설정값!$B$10-$C$3)/D11) -> 3 | F11: =1+INT(($F$3-$C$3)/D11) -> 2 | G11: 정보전 | H11: SP07
A12: 탈진 | B12: 상대 이번 턴 공격 피해 −N% | C12: 0.3 | D12: 4 | E12: =1+INT((설정값!$B$10-$C$3)/D12) -> 3 | F12: =1+INT(($F$3-$C$3)/D12) -> 2 | G12: 수호보다 약하고 쿨다운 짧음 | H12: SP08
A14: 스펠 ID: SP01~SP08(표 순서). 새 스펠은 다음 번호를 쓴다. 등록 후 변경 불가.

Sheet 피해계산기
A1: 피해 계산기
A2: 피해 = ATK × 계수 × 타수 × (1+버프) × 100/(100+DEF×(1−관통)) × 치명 × 폭주 − 실드
A4: 공격자 | B4: 움브라
A5: 방어자 | B5: 아우렐
A6: 카드 ID | B6: C02
A7: 턴 | B7: 7
A8: 버프 합(%) | B8: 0.3
A9: 치명 여부 | B9: 아니오
A10: 상대 실드 | B10: 0
A12: 공격자 ATK | B12: =INDEX(캐릭터!$G$5:$G$13,MATCH(B4,캐릭터!$A$5:$A$13,0)) -> 115
A13: 방어자 HP | B13: =INDEX(캐릭터!$F$5:$F$13,MATCH(B5,캐릭터!$A$5:$A$13,0)) -> 1200
A14: 방어자 DEF | B14: =INDEX(캐릭터!$H$5:$H$13,MATCH(B5,캐릭터!$A$5:$A$13,0)) -> 45
A15: 카드 종류 | B15: =INDEX(전투카드!$C$5:$C$38,MATCH(B6,전투카드!$A$5:$A$38,0)) -> 공격
A16: 카드 계수 | B16: =INDEX(전투카드!$G$5:$G$38,MATCH(B6,전투카드!$A$5:$A$38,0)) -> 1.8
A17: 타수 | B17: =IF(INDEX(전투카드!$H$5:$H$38,MATCH(B6,전투카드!$A$5:$A$38,0))="",1,INDEX(전투카드!$H$5:$H$38,MATCH(B6,전투카드!$A$5:$A$38,0))) -> 1
A18: 관통 | B18: =IF(INDEX(전투카드!$I$5:$I$38,MATCH(B6,전투카드!$A$5:$A$38,0))="",0,INDEX(전투카드!$I$5:$I$38,MATCH(B6,전투카드!$A$5:$A$38,0))) -> 0
A19: 폭주 배율 | B19: =IF(B7>=설정값!$B$11,1+(B7-설정값!$B$11+1)*설정값!$B$12,1) -> 1.25
A20: 치명 배율 | B20: =IF(B9="예",설정값!$B$26,1) -> 1
A21: 방어 경감 | B21: =100/(100+B14*(1-B18)) -> 0.68965517
A22: 피해(실드 전) | B22: =IF(B15="공격",B12*B16*B17*(1+B8)*B21*B20*B19,0) -> 231.98276
A23: 최종 피해 | B23: =MAX(0,B22-B10) -> 231.98276
A24: 방어자 HP 대비 | B24: =B23/B13 -> 0.19331897
A25: 같은 피해로 처치까지(타) | B25: =IF(B23>0,ROUNDUP(B13/B23,0),"-") -> 6
A27: 매트릭스: 강타(C02) 1회, 1턴, 버프·치명 없음 → 방어자 HP 대비 %
A28: 공격자 ↓ / 방어자 → | B28: 아우렐 | C28: 피로스 | D28: 이그니스 | E28: 셀레네 | F28: 실피 | G28: 테티스 | H28: 움브라 | I28: 실렌티아 | J28: 모르테
A29: 아우렐 | B29: =INDEX(캐릭터!$G$5:$G$13,MATCH($A29,캐릭터!$A$5:$A$13,0))*INDEX(전투카드!$G$5:$G$38,MATCH("C02",전투카드!$A$5:$A$38,0))*100/(100+INDEX(캐릭터!$H$5:$H$13,MATCH(B$28,캐릭터!$A$5:$A$13,0)))/INDEX(캐릭터!$F$5:$F$13,MATCH(B$28,캐릭터!$A$5:$A$13,0)) -> 0.087931034 | C29: =INDEX(캐릭터!$G$5:$G$13,MATCH($A29,캐릭터!$A$5:$A$13,0))*INDEX(전투카드!$G$5:$G$38,MATCH("C02",전투카드!$A$5:$A$38,0))*100/(100+INDEX(캐릭터!$H$5:$H$13,MATCH(C$28,캐릭터!$A$5:$A$13,0)))/INDEX(캐릭터!$F$5:$F$13,MATCH(C$28,캐릭터!$A$5:$A$13,0)) -> 0.10457963 | D29: =INDEX(캐릭터!$G$5:$G$13,MATCH($A29,캐릭터!$A$5:$A$13,0))*INDEX(전투카드!$G$5:$G$38,MATCH("C02",전투카드!$A$5:$A$38,0))*100/(100+INDEX(캐릭터!$H$5:$H$13,MATCH(D$28,캐릭터!$A$5:$A$13,0)))/INDEX(캐릭터!$F$5:$F$13,MATCH(D$28,캐릭터!$A$5:$A$13,0)) -> 0.11503759 | E29: =INDEX(캐릭터!$G$5:$G$13,MATCH($A29,캐릭터!$A$5:$A$13,0))*INDEX(전투카드!$G$5:$G$38,MATCH("C02",전투카드!$A$5:$A$38,0))*100/(100+INDEX(캐릭터!$H$5:$H$13,MATCH(E$28,캐릭터!$A$5:$A$13,0)))/INDEX(캐릭터!$F$5:$F$13,MATCH(E$28,캐릭터!$A$5:$A$13,0)) -> 0.097142857 | F29: =INDEX(캐릭터!$G$5:$G$13,MATCH($A29,캐릭터!$A$5:$A$13,0))*INDEX(전투카드!$G$5:$G$38,MATCH("C02",전투카드!$A$5:$A$38,0))*100/(100+INDEX(캐릭터!$H$5:$H$13,MATCH(F$28,캐릭터!$A$5:$A$13,0)))/INDEX(캐릭터!$F$5:$F$13,MATCH(F$28,캐릭터!$A$5:$A$13,0)) -> 0.11333333 | G29: =INDEX(캐릭터!$G$5:$G$13,MATCH($A29,캐릭터!$A$5:$A$13,0))*INDEX(전투카드!$G$5:$G$38,MATCH("C02",전투카드!$A$5:$A$38,0))*100/(100+INDEX(캐릭터!$H$5:$H$13,MATCH(G$28,캐릭터!$A$5:$A$13,0)))/INDEX(캐릭터!$F$5:$F$13,MATCH(G$28,캐릭터!$A$5:$A$13,0)) -> 0.10049261 | H29: =INDEX(캐릭터!$G$5:$G$13,MATCH($A29,캐릭터!$A$5:$A$13,0))*INDEX(전투카드!$G$5:$G$38,MATCH("C02",전투카드!$A$5:$A$38,0))*100/(100+INDEX(캐릭터!$H$5:$H$13,MATCH(H$28,캐릭터!$A$5:$A$13,0)))/INDEX(캐릭터!$F$5:$F$13,MATCH(H$28,캐릭터!$A$5:$A$13,0)) -> 0.12878788 | I29: =INDEX(캐릭터!$G$5:$G$13,MATCH($A29,캐릭터!$A$5:$A$13,0))*INDEX(전투카드!$G$5:$G$38,MATCH("C02",전투카드!$A$5:$A$38,0))*100/(100+INDEX(캐릭터!$H$5:$H$13,MATCH(I$28,캐릭터!$A$5:$A$13,0)))/INDEX(캐릭터!$F$5:$F$13,MATCH(I$28,캐릭터!$A$5:$A$13,0)) -> 0.11395799 | J29: =INDEX(캐릭터!$G$5:$G$13,MATCH($A29,캐릭터!$A$5:$A$13,0))*INDEX(전투카드!$G$5:$G$38,MATCH("C02",전투카드!$A$5:$A$38,0))*100/(100+INDEX(캐릭터!$H$5:$H$13,MATCH(J$28,캐릭터!$A$5:$A$13,0)))/INDEX(캐릭터!$F$5:$F$13,MATCH(J$28,캐릭터!$A$5:$A$13,0)) -> 0.083606557
A30: 피로스 | B30: =INDEX(캐릭터!$G$5:$G$13,MATCH($A30,캐릭터!$A$5:$A$13,0))*INDEX(전투카드!$G$5:$G$38,MATCH("C02",전투카드!$A$5:$A$38,0))*100/(100+INDEX(캐릭터!$H$5:$H$13,MATCH(B$28,캐릭터!$A$5:$A$13,0)))/INDEX(캐릭터!$F$5:$F$13,MATCH(B$28,캐릭터!$A$5:$A$13,0)) -> 0.11172414 | C30: =INDEX(캐릭터!$G$5:$G$13,MATCH($A30,캐릭터!$A$5:$A$13,0))*INDEX(전투카드!$G$5:$G$38,MATCH("C02",전투카드!$A$5:$A$38,0))*100/(100+INDEX(캐릭터!$H$5:$H$13,MATCH(C$28,캐릭터!$A$5:$A$13,0)))/INDEX(캐릭터!$F$5:$F$13,MATCH(C$28,캐릭터!$A$5:$A$13,0)) -> 0.13287765 | D30: =INDEX(캐릭터!$G$5:$G$13,MATCH($A30,캐릭터!$A$5:$A$13,0))*INDEX(전투카드!$G$5:$G$38,MATCH("C02",전투카드!$A$5:$A$38,0))*100/(100+INDEX(캐릭터!$H$5:$H$13,MATCH(D$28,캐릭터!$A$5:$A$13,0)))/INDEX(캐릭터!$F$5:$F$13,MATCH(D$28,캐릭터!$A$5:$A$13,0)) -> 0.14616541 | E30: =INDEX(캐릭터!$G$5:$G$13,MATCH($A30,캐릭터!$A$5:$A$13,0))*INDEX(전투카드!$G$5:$G$38,MATCH("C02",전투카드!$A$5:$A$38,0))*100/(100+INDEX(캐릭터!$H$5:$H$13,MATCH(E$28,캐릭터!$A$5:$A$13,0)))/INDEX(캐릭터!$F$5:$F$13,MATCH(E$28,캐릭터!$A$5:$A$13,0)) -> 0.12342857 | F30: =INDEX(캐릭터!$G$5:$G$13,MATCH($A30,캐릭터!$A$5:$A$13,0))*INDEX(전투카드!$G$5:$G$38,MATCH("C02",전투카드!$A$5:$A$38,0))*100/(100+INDEX(캐릭터!$H$5:$H$13,MATCH(F$28,캐릭터!$A$5:$A$13,0)))/INDEX(캐릭터!$F$5:$F$13,MATCH(F$28,캐릭터!$A$5:$A$13,0)) -> 0.144 | G30: =INDEX(캐릭터!$G$5:$G$13,MATCH($A30,캐릭터!$A$5:$A$13,0))*INDEX(전투카드!$G$5:$G$38,MATCH("C02",전투카드!$A$5:$A$38,0))*100/(100+INDEX(캐릭터!$H$5:$H$13,MATCH(G$28,캐릭터!$A$5:$A$13,0)))/INDEX(캐릭터!$F$5:$F$13,MATCH(G$28,캐릭터!$A$5:$A$13,0)) -> 0.12768473 | H30: =INDEX(캐릭터!$G$5:$G$13,MATCH($A30,캐릭터!$A$5:$A$13,0))*INDEX(전투카드!$G$5:$G$38,MATCH("C02",전투카드!$A$5:$A$38,0))*100/(100+INDEX(캐릭터!$H$5:$H$13,MATCH(H$28,캐릭터!$A$5:$A$13,0)))/INDEX(캐릭터!$F$5:$F$13,MATCH(H$28,캐릭터!$A$5:$A$13,0)) -> 0.16363636 | I30: =INDEX(캐릭터!$G$5:$G$13,MATCH($A30,캐릭터!$A$5:$A$13,0))*INDEX(전투카드!$G$5:$G$38,MATCH("C02",전투카드!$A$5:$A$38,0))*100/(100+INDEX(캐릭터!$H$5:$H$13,MATCH(I$28,캐릭터!$A$5:$A$13,0)))/INDEX(캐릭터!$F$5:$F$13,MATCH(I$28,캐릭터!$A$5:$A$13,0)) -> 0.14479368 | J30: =INDEX(캐릭터!$G$5:$G$13,MATCH($A30,캐릭터!$A$5:$A$13,0))*INDEX(전투카드!$G$5:$G$38,MATCH("C02",전투카드!$A$5:$A$38,0))*100/(100+INDEX(캐릭터!$H$5:$H$13,MATCH(J$28,캐릭터!$A$5:$A$13,0)))/INDEX(캐릭터!$F$5:$F$13,MATCH(J$28,캐릭터!$A$5:$A$13,0)) -> 0.10622951
A31: 이그니스 | B31: =INDEX(캐릭터!$G$5:$G$13,MATCH($A31,캐릭터!$A$5:$A$13,0))*INDEX(전투카드!$G$5:$G$38,MATCH("C02",전투카드!$A$5:$A$38,0))*100/(100+INDEX(캐릭터!$H$5:$H$13,MATCH(B$28,캐릭터!$A$5:$A$13,0)))/INDEX(캐릭터!$F$5:$F$13,MATCH(B$28,캐릭터!$A$5:$A$13,0)) -> 0.10344828 | C31: =INDEX(캐릭터!$G$5:$G$13,MATCH($A31,캐릭터!$A$5:$A$13,0))*INDEX(전투카드!$G$5:$G$38,MATCH("C02",전투카드!$A$5:$A$38,0))*100/(100+INDEX(캐릭터!$H$5:$H$13,MATCH(C$28,캐릭터!$A$5:$A$13,0)))/INDEX(캐릭터!$F$5:$F$13,MATCH(C$28,캐릭터!$A$5:$A$13,0)) -> 0.12303486 | D31: =INDEX(캐릭터!$G$5:$G$13,MATCH($A31,캐릭터!$A$5:$A$13,0))*INDEX(전투카드!$G$5:$G$38,MATCH("C02",전투카드!$A$5:$A$38,0))*100/(100+INDEX(캐릭터!$H$5:$H$13,MATCH(D$28,캐릭터!$A$5:$A$13,0)))/INDEX(캐릭터!$F$5:$F$13,MATCH(D$28,캐릭터!$A$5:$A$13,0)) -> 0.13533835 | E31: =INDEX(캐릭터!$G$5:$G$13,MATCH($A31,캐릭터!$A$5:$A$13,0))*INDEX(전투카드!$G$5:$G$38,MATCH("C02",전투카드!$A$5:$A$38,0))*100/(100+INDEX(캐릭터!$H$5:$H$13,MATCH(E$28,캐릭터!$A$5:$A$13,0)))/INDEX(캐릭터!$F$5:$F$13,MATCH(E$28,캐릭터!$A$5:$A$13,0)) -> 0.11428571 | F31: =INDEX(캐릭터!$G$5:$G$13,MATCH($A31,캐릭터!$A$5:$A$13,0))*INDEX(전투카드!$G$5:$G$38,MATCH("C02",전투카드!$A$5:$A$38,0))*100/(100+INDEX(캐릭터!$H$5:$H$13,MATCH(F$28,캐릭터!$A$5:$A$13,0)))/INDEX(캐릭터!$F$5:$F$13,MATCH(F$28,캐릭터!$A$5:$A$13,0)) -> 0.13333333 | G31: =INDEX(캐릭터!$G$5:$G$13,MATCH($A31,캐릭터!$A$5:$A$13,0))*INDEX(전투카드!$G$5:$G$38,MATCH("C02",전투카드!$A$5:$A$38,0))*100/(100+INDEX(캐릭터!$H$5:$H$13,MATCH(G$28,캐릭터!$A$5:$A$13,0)))/INDEX(캐릭터!$F$5:$F$13,MATCH(G$28,캐릭터!$A$5:$A$13,0)) -> 0.1182266 | H31: =INDEX(캐릭터!$G$5:$G$13,MATCH($A31,캐릭터!$A$5:$A$13,0))*INDEX(전투카드!$G$5:$G$38,MATCH("C02",전투카드!$A$5:$A$38,0))*100/(100+INDEX(캐릭터!$H$5:$H$13,MATCH(H$28,캐릭터!$A$5:$A$13,0)))/INDEX(캐릭터!$F$5:$F$13,MATCH(H$28,캐릭터!$A$5:$A$13,0)) -> 0.15151515 | I31: =INDEX(캐릭터!$G$5:$G$13,MATCH($A31,캐릭터!$A$5:$A$13,0))*INDEX(전투카드!$G$5:$G$38,MATCH("C02",전투카드!$A$5:$A$38,0))*100/(100+INDEX(캐릭터!$H$5:$H$13,MATCH(I$28,캐릭터!$A$5:$A$13,0)))/INDEX(캐릭터!$F$5:$F$13,MATCH(I$28,캐릭터!$A$5:$A$13,0)) -> 0.13406823 | J31: =INDEX(캐릭터!$G$5:$G$13,MATCH($A31,캐릭터!$A$5:$A$13,0))*INDEX(전투카드!$G$5:$G$38,MATCH("C02",전투카드!$A$5:$A$38,0))*100/(100+INDEX(캐릭터!$H$5:$H$13,MATCH(J$28,캐릭터!$A$5:$A$13,0)))/INDEX(캐릭터!$F$5:$F$13,MATCH(J$28,캐릭터!$A$5:$A$13,0)) -> 0.098360656
A32: 셀레네 | B32: =INDEX(캐릭터!$G$5:$G$13,MATCH($A32,캐릭터!$A$5:$A$13,0))*INDEX(전투카드!$G$5:$G$38,MATCH("C02",전투카드!$A$5:$A$38,0))*100/(100+INDEX(캐릭터!$H$5:$H$13,MATCH(B$28,캐릭터!$A$5:$A$13,0)))/INDEX(캐릭터!$F$5:$F$13,MATCH(B$28,캐릭터!$A$5:$A$13,0)) -> 0.093103448 | C32: =INDEX(캐릭터!$G$5:$G$13,MATCH($A32,캐릭터!$A$5:$A$13,0))*INDEX(전투카드!$G$5:$G$38,MATCH("C02",전투카드!$A$5:$A$38,0))*100/(100+INDEX(캐릭터!$H$5:$H$13,MATCH(C$28,캐릭터!$A$5:$A$13,0)))/INDEX(캐릭터!$F$5:$F$13,MATCH(C$28,캐릭터!$A$5:$A$13,0)) -> 0.11073137 | D32: =INDEX(캐릭터!$G$5:$G$13,MATCH($A32,캐릭터!$A$5:$A$13,0))*INDEX(전투카드!$G$5:$G$38,MATCH("C02",전투카드!$A$5:$A$38,0))*100/(100+INDEX(캐릭터!$H$5:$H$13,MATCH(D$28,캐릭터!$A$5:$A$13,0)))/INDEX(캐릭터!$F$5:$F$13,MATCH(D$28,캐릭터!$A$5:$A$13,0)) -> 0.12180451 | E32: =INDEX(캐릭터!$G$5:$G$13,MATCH($A32,캐릭터!$A$5:$A$13,0))*INDEX(전투카드!$G$5:$G$38,MATCH("C02",전투카드!$A$5:$A$38,0))*100/(100+INDEX(캐릭터!$H$5:$H$13,MATCH(E$28,캐릭터!$A$5:$A$13,0)))/INDEX(캐릭터!$F$5:$F$13,MATCH(E$28,캐릭터!$A$5:$A$13,0)) -> 0.10285714 | F32: =INDEX(캐릭터!$G$5:$G$13,MATCH($A32,캐릭터!$A$5:$A$13,0))*INDEX(전투카드!$G$5:$G$38,MATCH("C02",전투카드!$A$5:$A$38,0))*100/(100+INDEX(캐릭터!$H$5:$H$13,MATCH(F$28,캐릭터!$A$5:$A$13,0)))/INDEX(캐릭터!$F$5:$F$13,MATCH(F$28,캐릭터!$A$5:$A$13,0)) -> 0.12 | G32: =INDEX(캐릭터!$G$5:$G$13,MATCH($A32,캐릭터!$A$5:$A$13,0))*INDEX(전투카드!$G$5:$G$38,MATCH("C02",전투카드!$A$5:$A$38,0))*100/(100+INDEX(캐릭터!$H$5:$H$13,MATCH(G$28,캐릭터!$A$5:$A$13,0)))/INDEX(캐릭터!$F$5:$F$13,MATCH(G$28,캐릭터!$A$5:$A$13,0)) -> 0.10640394 | H32: =INDEX(캐릭터!$G$5:$G$13,MATCH($A32,캐릭터!$A$5:$A$13,0))*INDEX(전투카드!$G$5:$G$38,MATCH("C02",전투카드!$A$5:$A$38,0))*100/(100+INDEX(캐릭터!$H$5:$H$13,MATCH(H$28,캐릭터!$A$5:$A$13,0)))/INDEX(캐릭터!$F$5:$F$13,MATCH(H$28,캐릭터!$A$5:$A$13,0)) -> 0.13636364 | I32: =INDEX(캐릭터!$G$5:$G$13,MATCH($A32,캐릭터!$A$5:$A$13,0))*INDEX(전투카드!$G$5:$G$38,MATCH("C02",전투카드!$A$5:$A$38,0))*100/(100+INDEX(캐릭터!$H$5:$H$13,MATCH(I$28,캐릭터!$A$5:$A$13,0)))/INDEX(캐릭터!$F$5:$F$13,MATCH(I$28,캐릭터!$A$5:$A$13,0)) -> 0.1206614 | J32: =INDEX(캐릭터!$G$5:$G$13,MATCH($A32,캐릭터!$A$5:$A$13,0))*INDEX(전투카드!$G$5:$G$38,MATCH("C02",전투카드!$A$5:$A$38,0))*100/(100+INDEX(캐릭터!$H$5:$H$13,MATCH(J$28,캐릭터!$A$5:$A$13,0)))/INDEX(캐릭터!$F$5:$F$13,MATCH(J$28,캐릭터!$A$5:$A$13,0)) -> 0.08852459
A33: 실피 | B33: =INDEX(캐릭터!$G$5:$G$13,MATCH($A33,캐릭터!$A$5:$A$13,0))*INDEX(전투카드!$G$5:$G$38,MATCH("C02",전투카드!$A$5:$A$38,0))*100/(100+INDEX(캐릭터!$H$5:$H$13,MATCH(B$28,캐릭터!$A$5:$A$13,0)))/INDEX(캐릭터!$F$5:$F$13,MATCH(B$28,캐릭터!$A$5:$A$13,0)) -> 0.10758621 | C33: =INDEX(캐릭터!$G$5:$G$13,MATCH($A33,캐릭터!$A$5:$A$13,0))*INDEX(전투카드!$G$5:$G$38,MATCH("C02",전투카드!$A$5:$A$38,0))*100/(100+INDEX(캐릭터!$H$5:$H$13,MATCH(C$28,캐릭터!$A$5:$A$13,0)))/INDEX(캐릭터!$F$5:$F$13,MATCH(C$28,캐릭터!$A$5:$A$13,0)) -> 0.12795625 | D33: =INDEX(캐릭터!$G$5:$G$13,MATCH($A33,캐릭터!$A$5:$A$13,0))*INDEX(전투카드!$G$5:$G$38,MATCH("C02",전투카드!$A$5:$A$38,0))*100/(100+INDEX(캐릭터!$H$5:$H$13,MATCH(D$28,캐릭터!$A$5:$A$13,0)))/INDEX(캐릭터!$F$5:$F$13,MATCH(D$28,캐릭터!$A$5:$A$13,0)) -> 0.14075188 | E33: =INDEX(캐릭터!$G$5:$G$13,MATCH($A33,캐릭터!$A$5:$A$13,0))*INDEX(전투카드!$G$5:$G$38,MATCH("C02",전투카드!$A$5:$A$38,0))*100/(100+INDEX(캐릭터!$H$5:$H$13,MATCH(E$28,캐릭터!$A$5:$A$13,0)))/INDEX(캐릭터!$F$5:$F$13,MATCH(E$28,캐릭터!$A$5:$A$13,0)) -> 0.11885714 | F33: =INDEX(캐릭터!$G$5:$G$13,MATCH($A33,캐릭터!$A$5:$A$13,0))*INDEX(전투카드!$G$5:$G$38,MATCH("C02",전투카드!$A$5:$A$38,0))*100/(100+INDEX(캐릭터!$H$5:$H$13,MATCH(F$28,캐릭터!$A$5:$A$13,0)))/INDEX(캐릭터!$F$5:$F$13,MATCH(F$28,캐릭터!$A$5:$A$13,0)) -> 0.13866667 | G33: =INDEX(캐릭터!$G$5:$G$13,MATCH($A33,캐릭터!$A$5:$A$13,0))*INDEX(전투카드!$G$5:$G$38,MATCH("C02",전투카드!$A$5:$A$38,0))*100/(100+INDEX(캐릭터!$H$5:$H$13,MATCH(G$28,캐릭터!$A$5:$A$13,0)))/INDEX(캐릭터!$F$5:$F$13,MATCH(G$28,캐릭터!$A$5:$A$13,0)) -> 0.12295567 | H33: =INDEX(캐릭터!$G$5:$G$13,MATCH($A33,캐릭터!$A$5:$A$13,0))*INDEX(전투카드!$G$5:$G$38,MATCH("C02",전투카드!$A$5:$A$38,0))*100/(100+INDEX(캐릭터!$H$5:$H$13,MATCH(H$28,캐릭터!$A$5:$A$13,0)))/INDEX(캐릭터!$F$5:$F$13,MATCH(H$28,캐릭터!$A$5:$A$13,0)) -> 0.15757576 | I33: =INDEX(캐릭터!$G$5:$G$13,MATCH($A33,캐릭터!$A$5:$A$13,0))*INDEX(전투카드!$G$5:$G$38,MATCH("C02",전투카드!$A$5:$A$38,0))*100/(100+INDEX(캐릭터!$H$5:$H$13,MATCH(I$28,캐릭터!$A$5:$A$13,0)))/INDEX(캐릭터!$F$5:$F$13,MATCH(I$28,캐릭터!$A$5:$A$13,0)) -> 0.13943095 | J33: =INDEX(캐릭터!$G$5:$G$13,MATCH($A33,캐릭터!$A$5:$A$13,0))*INDEX(전투카드!$G$5:$G$38,MATCH("C02",전투카드!$A$5:$A$38,0))*100/(100+INDEX(캐릭터!$H$5:$H$13,MATCH(J$28,캐릭터!$A$5:$A$13,0)))/INDEX(캐릭터!$F$5:$F$13,MATCH(J$28,캐릭터!$A$5:$A$13,0)) -> 0.10229508
A34: 테티스 | B34: =INDEX(캐릭터!$G$5:$G$13,MATCH($A34,캐릭터!$A$5:$A$13,0))*INDEX(전투카드!$G$5:$G$38,MATCH("C02",전투카드!$A$5:$A$38,0))*100/(100+INDEX(캐릭터!$H$5:$H$13,MATCH(B$28,캐릭터!$A$5:$A$13,0)))/INDEX(캐릭터!$F$5:$F$13,MATCH(B$28,캐릭터!$A$5:$A$13,0)) -> 0.10344828 | C34: =INDEX(캐릭터!$G$5:$G$13,MATCH($A34,캐릭터!$A$5:$A$13,0))*INDEX(전투카드!$G$5:$G$38,MATCH("C02",전투카드!$A$5:$A$38,0))*100/(100+INDEX(캐릭터!$H$5:$H$13,MATCH(C$28,캐릭터!$A$5:$A$13,0)))/INDEX(캐릭터!$F$5:$F$13,MATCH(C$28,캐릭터!$A$5:$A$13,0)) -> 0.12303486 | D34: =INDEX(캐릭터!$G$5:$G$13,MATCH($A34,캐릭터!$A$5:$A$13,0))*INDEX(전투카드!$G$5:$G$38,MATCH("C02",전투카드!$A$5:$A$38,0))*100/(100+INDEX(캐릭터!$H$5:$H$13,MATCH(D$28,캐릭터!$A$5:$A$13,0)))/INDEX(캐릭터!$F$5:$F$13,MATCH(D$28,캐릭터!$A$5:$A$13,0)) -> 0.13533835 | E34: =INDEX(캐릭터!$G$5:$G$13,MATCH($A34,캐릭터!$A$5:$A$13,0))*INDEX(전투카드!$G$5:$G$38,MATCH("C02",전투카드!$A$5:$A$38,0))*100/(100+INDEX(캐릭터!$H$5:$H$13,MATCH(E$28,캐릭터!$A$5:$A$13,0)))/INDEX(캐릭터!$F$5:$F$13,MATCH(E$28,캐릭터!$A$5:$A$13,0)) -> 0.11428571 | F34: =INDEX(캐릭터!$G$5:$G$13,MATCH($A34,캐릭터!$A$5:$A$13,0))*INDEX(전투카드!$G$5:$G$38,MATCH("C02",전투카드!$A$5:$A$38,0))*100/(100+INDEX(캐릭터!$H$5:$H$13,MATCH(F$28,캐릭터!$A$5:$A$13,0)))/INDEX(캐릭터!$F$5:$F$13,MATCH(F$28,캐릭터!$A$5:$A$13,0)) -> 0.13333333 | G34: =INDEX(캐릭터!$G$5:$G$13,MATCH($A34,캐릭터!$A$5:$A$13,0))*INDEX(전투카드!$G$5:$G$38,MATCH("C02",전투카드!$A$5:$A$38,0))*100/(100+INDEX(캐릭터!$H$5:$H$13,MATCH(G$28,캐릭터!$A$5:$A$13,0)))/INDEX(캐릭터!$F$5:$F$13,MATCH(G$28,캐릭터!$A$5:$A$13,0)) -> 0.1182266 | H34: =INDEX(캐릭터!$G$5:$G$13,MATCH($A34,캐릭터!$A$5:$A$13,0))*INDEX(전투카드!$G$5:$G$38,MATCH("C02",전투카드!$A$5:$A$38,0))*100/(100+INDEX(캐릭터!$H$5:$H$13,MATCH(H$28,캐릭터!$A$5:$A$13,0)))/INDEX(캐릭터!$F$5:$F$13,MATCH(H$28,캐릭터!$A$5:$A$13,0)) -> 0.15151515 | I34: =INDEX(캐릭터!$G$5:$G$13,MATCH($A34,캐릭터!$A$5:$A$13,0))*INDEX(전투카드!$G$5:$G$38,MATCH("C02",전투카드!$A$5:$A$38,0))*100/(100+INDEX(캐릭터!$H$5:$H$13,MATCH(I$28,캐릭터!$A$5:$A$13,0)))/INDEX(캐릭터!$F$5:$F$13,MATCH(I$28,캐릭터!$A$5:$A$13,0)) -> 0.13406823 | J34: =INDEX(캐릭터!$G$5:$G$13,MATCH($A34,캐릭터!$A$5:$A$13,0))*INDEX(전투카드!$G$5:$G$38,MATCH("C02",전투카드!$A$5:$A$38,0))*100/(100+INDEX(캐릭터!$H$5:$H$13,MATCH(J$28,캐릭터!$A$5:$A$13,0)))/INDEX(캐릭터!$F$5:$F$13,MATCH(J$28,캐릭터!$A$5:$A$13,0)) -> 0.098360656
A35: 움브라 | B35: =INDEX(캐릭터!$G$5:$G$13,MATCH($A35,캐릭터!$A$5:$A$13,0))*INDEX(전투카드!$G$5:$G$38,MATCH("C02",전투카드!$A$5:$A$38,0))*100/(100+INDEX(캐릭터!$H$5:$H$13,MATCH(B$28,캐릭터!$A$5:$A$13,0)))/INDEX(캐릭터!$F$5:$F$13,MATCH(B$28,캐릭터!$A$5:$A$13,0)) -> 0.11896552 | C35: =INDEX(캐릭터!$G$5:$G$13,MATCH($A35,캐릭터!$A$5:$A$13,0))*INDEX(전투카드!$G$5:$G$38,MATCH("C02",전투카드!$A$5:$A$38,0))*100/(100+INDEX(캐릭터!$H$5:$H$13,MATCH(C$28,캐릭터!$A$5:$A$13,0)))/INDEX(캐릭터!$F$5:$F$13,MATCH(C$28,캐릭터!$A$5:$A$13,0)) -> 0.14149009 | D35: =INDEX(캐릭터!$G$5:$G$13,MATCH($A35,캐릭터!$A$5:$A$13,0))*INDEX(전투카드!$G$5:$G$38,MATCH("C02",전투카드!$A$5:$A$38,0))*100/(100+INDEX(캐릭터!$H$5:$H$13,MATCH(D$28,캐릭터!$A$5:$A$13,0)))/INDEX(캐릭터!$F$5:$F$13,MATCH(D$28,캐릭터!$A$5:$A$13,0)) -> 0.1556391 | E35: =INDEX(캐릭터!$G$5:$G$13,MATCH($A35,캐릭터!$A$5:$A$13,0))*INDEX(전투카드!$G$5:$G$38,MATCH("C02",전투카드!$A$5:$A$38,0))*100/(100+INDEX(캐릭터!$H$5:$H$13,MATCH(E$28,캐릭터!$A$5:$A$13,0)))/INDEX(캐릭터!$F$5:$F$13,MATCH(E$28,캐릭터!$A$5:$A$13,0)) -> 0.13142857 | F35: =INDEX(캐릭터!$G$5:$G$13,MATCH($A35,캐릭터!$A$5:$A$13,0))*INDEX(전투카드!$G$5:$G$38,MATCH("C02",전투카드!$A$5:$A$38,0))*100/(100+INDEX(캐릭터!$H$5:$H$13,MATCH(F$28,캐릭터!$A$5:$A$13,0)))/INDEX(캐릭터!$F$5:$F$13,MATCH(F$28,캐릭터!$A$5:$A$13,0)) -> 0.15333333 | G35: =INDEX(캐릭터!$G$5:$G$13,MATCH($A35,캐릭터!$A$5:$A$13,0))*INDEX(전투카드!$G$5:$G$38,MATCH("C02",전투카드!$A$5:$A$38,0))*100/(100+INDEX(캐릭터!$H$5:$H$13,MATCH(G$28,캐릭터!$A$5:$A$13,0)))/INDEX(캐릭터!$F$5:$F$13,MATCH(G$28,캐릭터!$A$5:$A$13,0)) -> 0.13596059 | H35: =INDEX(캐릭터!$G$5:$G$13,MATCH($A35,캐릭터!$A$5:$A$13,0))*INDEX(전투카드!$G$5:$G$38,MATCH("C02",전투카드!$A$5:$A$38,0))*100/(100+INDEX(캐릭터!$H$5:$H$13,MATCH(H$28,캐릭터!$A$5:$A$13,0)))/INDEX(캐릭터!$F$5:$F$13,MATCH(H$28,캐릭터!$A$5:$A$13,0)) -> 0.17424242 | I35: =INDEX(캐릭터!$G$5:$G$13,MATCH($A35,캐릭터!$A$5:$A$13,0))*INDEX(전투카드!$G$5:$G$38,MATCH("C02",전투카드!$A$5:$A$38,0))*100/(100+INDEX(캐릭터!$H$5:$H$13,MATCH(I$28,캐릭터!$A$5:$A$13,0)))/INDEX(캐릭터!$F$5:$F$13,MATCH(I$28,캐릭터!$A$5:$A$13,0)) -> 0.15417846 | J35: =INDEX(캐릭터!$G$5:$G$13,MATCH($A35,캐릭터!$A$5:$A$13,0))*INDEX(전투카드!$G$5:$G$38,MATCH("C02",전투카드!$A$5:$A$38,0))*100/(100+INDEX(캐릭터!$H$5:$H$13,MATCH(J$28,캐릭터!$A$5:$A$13,0)))/INDEX(캐릭터!$F$5:$F$13,MATCH(J$28,캐릭터!$A$5:$A$13,0)) -> 0.11311475
A36: 실렌티아 | B36: =INDEX(캐릭터!$G$5:$G$13,MATCH($A36,캐릭터!$A$5:$A$13,0))*INDEX(전투카드!$G$5:$G$38,MATCH("C02",전투카드!$A$5:$A$38,0))*100/(100+INDEX(캐릭터!$H$5:$H$13,MATCH(B$28,캐릭터!$A$5:$A$13,0)))/INDEX(캐릭터!$F$5:$F$13,MATCH(B$28,캐릭터!$A$5:$A$13,0)) -> 0.10862069 | C36: =INDEX(캐릭터!$G$5:$G$13,MATCH($A36,캐릭터!$A$5:$A$13,0))*INDEX(전투카드!$G$5:$G$38,MATCH("C02",전투카드!$A$5:$A$38,0))*100/(100+INDEX(캐릭터!$H$5:$H$13,MATCH(C$28,캐릭터!$A$5:$A$13,0)))/INDEX(캐릭터!$F$5:$F$13,MATCH(C$28,캐릭터!$A$5:$A$13,0)) -> 0.1291866 | D36: =INDEX(캐릭터!$G$5:$G$13,MATCH($A36,캐릭터!$A$5:$A$13,0))*INDEX(전투카드!$G$5:$G$38,MATCH("C02",전투카드!$A$5:$A$38,0))*100/(100+INDEX(캐릭터!$H$5:$H$13,MATCH(D$28,캐릭터!$A$5:$A$13,0)))/INDEX(캐릭터!$F$5:$F$13,MATCH(D$28,캐릭터!$A$5:$A$13,0)) -> 0.14210526 | E36: =INDEX(캐릭터!$G$5:$G$13,MATCH($A36,캐릭터!$A$5:$A$13,0))*INDEX(전투카드!$G$5:$G$38,MATCH("C02",전투카드!$A$5:$A$38,0))*100/(100+INDEX(캐릭터!$H$5:$H$13,MATCH(E$28,캐릭터!$A$5:$A$13,0)))/INDEX(캐릭터!$F$5:$F$13,MATCH(E$28,캐릭터!$A$5:$A$13,0)) -> 0.12 | F36: =INDEX(캐릭터!$G$5:$G$13,MATCH($A36,캐릭터!$A$5:$A$13,0))*INDEX(전투카드!$G$5:$G$38,MATCH("C02",전투카드!$A$5:$A$38,0))*100/(100+INDEX(캐릭터!$H$5:$H$13,MATCH(F$28,캐릭터!$A$5:$A$13,0)))/INDEX(캐릭터!$F$5:$F$13,MATCH(F$28,캐릭터!$A$5:$A$13,0)) -> 0.14 | G36: =INDEX(캐릭터!$G$5:$G$13,MATCH($A36,캐릭터!$A$5:$A$13,0))*INDEX(전투카드!$G$5:$G$38,MATCH("C02",전투카드!$A$5:$A$38,0))*100/(100+INDEX(캐릭터!$H$5:$H$13,MATCH(G$28,캐릭터!$A$5:$A$13,0)))/INDEX(캐릭터!$F$5:$F$13,MATCH(G$28,캐릭터!$A$5:$A$13,0)) -> 0.12413793 | H36: =INDEX(캐릭터!$G$5:$G$13,MATCH($A36,캐릭터!$A$5:$A$13,0))*INDEX(전투카드!$G$5:$G$38,MATCH("C02",전투카드!$A$5:$A$38,0))*100/(100+INDEX(캐릭터!$H$5:$H$13,MATCH(H$28,캐릭터!$A$5:$A$13,0)))/INDEX(캐릭터!$F$5:$F$13,MATCH(H$28,캐릭터!$A$5:$A$13,0)) -> 0.15909091 | I36: =INDEX(캐릭터!$G$5:$G$13,MATCH($A36,캐릭터!$A$5:$A$13,0))*INDEX(전투카드!$G$5:$G$38,MATCH("C02",전투카드!$A$5:$A$38,0))*100/(100+INDEX(캐릭터!$H$5:$H$13,MATCH(I$28,캐릭터!$A$5:$A$13,0)))/INDEX(캐릭터!$F$5:$F$13,MATCH(I$28,캐릭터!$A$5:$A$13,0)) -> 0.14077164 | J36: =INDEX(캐릭터!$G$5:$G$13,MATCH($A36,캐릭터!$A$5:$A$13,0))*INDEX(전투카드!$G$5:$G$38,MATCH("C02",전투카드!$A$5:$A$38,0))*100/(100+INDEX(캐릭터!$H$5:$H$13,MATCH(J$28,캐릭터!$A$5:$A$13,0)))/INDEX(캐릭터!$F$5:$F$13,MATCH(J$28,캐릭터!$A$5:$A$13,0)) -> 0.10327869
A37: 모르테 | B37: =INDEX(캐릭터!$G$5:$G$13,MATCH($A37,캐릭터!$A$5:$A$13,0))*INDEX(전투카드!$G$5:$G$38,MATCH("C02",전투카드!$A$5:$A$38,0))*100/(100+INDEX(캐릭터!$H$5:$H$13,MATCH(B$28,캐릭터!$A$5:$A$13,0)))/INDEX(캐릭터!$F$5:$F$13,MATCH(B$28,캐릭터!$A$5:$A$13,0)) -> 0.082758621 | C37: =INDEX(캐릭터!$G$5:$G$13,MATCH($A37,캐릭터!$A$5:$A$13,0))*INDEX(전투카드!$G$5:$G$38,MATCH("C02",전투카드!$A$5:$A$38,0))*100/(100+INDEX(캐릭터!$H$5:$H$13,MATCH(C$28,캐릭터!$A$5:$A$13,0)))/INDEX(캐릭터!$F$5:$F$13,MATCH(C$28,캐릭터!$A$5:$A$13,0)) -> 0.098427888 | D37: =INDEX(캐릭터!$G$5:$G$13,MATCH($A37,캐릭터!$A$5:$A$13,0))*INDEX(전투카드!$G$5:$G$38,MATCH("C02",전투카드!$A$5:$A$38,0))*100/(100+INDEX(캐릭터!$H$5:$H$13,MATCH(D$28,캐릭터!$A$5:$A$13,0)))/INDEX(캐릭터!$F$5:$F$13,MATCH(D$28,캐릭터!$A$5:$A$13,0)) -> 0.10827068 | E37: =INDEX(캐릭터!$G$5:$G$13,MATCH($A37,캐릭터!$A$5:$A$13,0))*INDEX(전투카드!$G$5:$G$38,MATCH("C02",전투카드!$A$5:$A$38,0))*100/(100+INDEX(캐릭터!$H$5:$H$13,MATCH(E$28,캐릭터!$A$5:$A$13,0)))/INDEX(캐릭터!$F$5:$F$13,MATCH(E$28,캐릭터!$A$5:$A$13,0)) -> 0.091428571 | F37: =INDEX(캐릭터!$G$5:$G$13,MATCH($A37,캐릭터!$A$5:$A$13,0))*INDEX(전투카드!$G$5:$G$38,MATCH("C02",전투카드!$A$5:$A$38,0))*100/(100+INDEX(캐릭터!$H$5:$H$13,MATCH(F$28,캐릭터!$A$5:$A$13,0)))/INDEX(캐릭터!$F$5:$F$13,MATCH(F$28,캐릭터!$A$5:$A$13,0)) -> 0.10666667 | G37: =INDEX(캐릭터!$G$5:$G$13,MATCH($A37,캐릭터!$A$5:$A$13,0))*INDEX(전투카드!$G$5:$G$38,MATCH("C02",전투카드!$A$5:$A$38,0))*100/(100+INDEX(캐릭터!$H$5:$H$13,MATCH(G$28,캐릭터!$A$5:$A$13,0)))/INDEX(캐릭터!$F$5:$F$13,MATCH(G$28,캐릭터!$A$5:$A$13,0)) -> 0.094581281 | H37: =INDEX(캐릭터!$G$5:$G$13,MATCH($A37,캐릭터!$A$5:$A$13,0))*INDEX(전투카드!$G$5:$G$38,MATCH("C02",전투카드!$A$5:$A$38,0))*100/(100+INDEX(캐릭터!$H$5:$H$13,MATCH(H$28,캐릭터!$A$5:$A$13,0)))/INDEX(캐릭터!$F$5:$F$13,MATCH(H$28,캐릭터!$A$5:$A$13,0)) -> 0.12121212 | I37: =INDEX(캐릭터!$G$5:$G$13,MATCH($A37,캐릭터!$A$5:$A$13,0))*INDEX(전투카드!$G$5:$G$38,MATCH("C02",전투카드!$A$5:$A$38,0))*100/(100+INDEX(캐릭터!$H$5:$H$13,MATCH(I$28,캐릭터!$A$5:$A$13,0)))/INDEX(캐릭터!$F$5:$F$13,MATCH(I$28,캐릭터!$A$5:$A$13,0)) -> 0.10725458 | J37: =INDEX(캐릭터!$G$5:$G$13,MATCH($A37,캐릭터!$A$5:$A$13,0))*INDEX(전투카드!$G$5:$G$38,MATCH("C02",전투카드!$A$5:$A$38,0))*100/(100+INDEX(캐릭터!$H$5:$H$13,MATCH(J$28,캐릭터!$A$5:$A$13,0)))/INDEX(캐릭터!$F$5:$F$13,MATCH(J$28,캐릭터!$A$5:$A$13,0)) -> 0.078688525

Sheet 랭크_승점
A1: 랭크 단계, 기준 MMR, 승점(RP)
A2: AI전 RP = 사람전 RP × (1 − NN%). 설정값 시트의 NN%를 바꾸면 G~J열이 다시 계산된다.
A3: 기준 MMR 시작 | C3: 800 | D3: 단계당 MMR 증가 | F3: 50
A4: 순번 | B4: 단계 | C4: 누적 RP 시작 | D4: 기준 MMR | E4: 패배 감소 배율 | F4: 하한선 | G4: 승리 RP(사람) | H4: 승리 RP(AI) | I4: 패배 RP(사람) | J4: 패배 RP(AI) | K4: AI 대체 | L4: 리셋 후 시작 단계
A5: 1 | B5: 브론즈 III | C5: =(A5-1)*설정값!$B$25 -> 0 | D5: =$C$3+(A5-1)*$F$3 -> 800 | E5: 0 | G5: =설정값!$B$14 -> 25 | H5: =ROUND(G5*(1-설정값!$B$5),0) -> 15 | I5: =-ROUND(설정값!$B$15*E5,0) -> 0 | J5: =-ROUND(설정값!$B$15*E5*(1-설정값!$B$5),0) -> 0 | K5: =IF(A5>=설정값!$B$7,"없음","있음") -> 있음 | L5: =INDEX($B$5:$B$20,MAX(1,A5-설정값!$B$23)) -> 브론즈 III
A6: 2 | B6: 브론즈 II | C6: =(A6-1)*설정값!$B$25 -> 100 | D6: =$C$3+(A6-1)*$F$3 -> 850 | E6: 0 | G6: =설정값!$B$14 -> 25 | H6: =ROUND(G6*(1-설정값!$B$5),0) -> 15 | I6: =-ROUND(설정값!$B$15*E6,0) -> 0 | J6: =-ROUND(설정값!$B$15*E6*(1-설정값!$B$5),0) -> 0 | K6: =IF(A6>=설정값!$B$7,"없음","있음") -> 있음 | L6: =INDEX($B$5:$B$20,MAX(1,A6-설정값!$B$23)) -> 브론즈 III
A7: 3 | B7: 브론즈 I | C7: =(A7-1)*설정값!$B$25 -> 200 | D7: =$C$3+(A7-1)*$F$3 -> 900 | E7: 0 | G7: =설정값!$B$14 -> 25 | H7: =ROUND(G7*(1-설정값!$B$5),0) -> 15 | I7: =-ROUND(설정값!$B$15*E7,0) -> 0 | J7: =-ROUND(설정값!$B$15*E7*(1-설정값!$B$5),0) -> 0 | K7: =IF(A7>=설정값!$B$7,"없음","있음") -> 있음 | L7: =INDEX($B$5:$B$20,MAX(1,A7-설정값!$B$23)) -> 브론즈 III
A8: 4 | B8: 실버 III | C8: =(A8-1)*설정값!$B$25 -> 300 | D8: =$C$3+(A8-1)*$F$3 -> 950 | E8: 0.5 | G8: =설정값!$B$14 -> 25 | H8: =ROUND(G8*(1-설정값!$B$5),0) -> 15 | I8: =-ROUND(설정값!$B$15*E8,0) -> -10 | J8: =-ROUND(설정값!$B$15*E8*(1-설정값!$B$5),0) -> -6 | K8: =IF(A8>=설정값!$B$7,"없음","있음") -> 있음 | L8: =INDEX($B$5:$B$20,MAX(1,A8-설정값!$B$23)) -> 브론즈 III
A9: 5 | B9: 실버 II | C9: =(A9-1)*설정값!$B$25 -> 400 | D9: =$C$3+(A9-1)*$F$3 -> 1000 | E9: 0.5 | G9: =설정값!$B$14 -> 25 | H9: =ROUND(G9*(1-설정값!$B$5),0) -> 15 | I9: =-ROUND(설정값!$B$15*E9,0) -> -10 | J9: =-ROUND(설정값!$B$15*E9*(1-설정값!$B$5),0) -> -6 | K9: =IF(A9>=설정값!$B$7,"없음","있음") -> 있음 | L9: =INDEX($B$5:$B$20,MAX(1,A9-설정값!$B$23)) -> 브론즈 III
A10: 6 | B10: 실버 I | C10: =(A10-1)*설정값!$B$25 -> 500 | D10: =$C$3+(A10-1)*$F$3 -> 1050 | E10: 0.5 | G10: =설정값!$B$14 -> 25 | H10: =ROUND(G10*(1-설정값!$B$5),0) -> 15 | I10: =-ROUND(설정값!$B$15*E10,0) -> -10 | J10: =-ROUND(설정값!$B$15*E10*(1-설정값!$B$5),0) -> -6 | K10: =IF(A10>=설정값!$B$7,"없음","있음") -> 있음 | L10: =INDEX($B$5:$B$20,MAX(1,A10-설정값!$B$23)) -> 브론즈 II
A11: 7 | B11: 골드 III | C11: =(A11-1)*설정값!$B$25 -> 600 | D11: =$C$3+(A11-1)*$F$3 -> 1100 | E11: 1 | F11: 하한선 | G11: =설정값!$B$14 -> 25 | H11: =ROUND(G11*(1-설정값!$B$5),0) -> 15 | I11: =-ROUND(설정값!$B$15*E11,0) -> -20 | J11: =-ROUND(설정값!$B$15*E11*(1-설정값!$B$5),0) -> -12 | K11: =IF(A11>=설정값!$B$7,"없음","있음") -> 있음 | L11: =INDEX($B$5:$B$20,MAX(1,A11-설정값!$B$23)) -> 브론즈 I
A12: 8 | B12: 골드 II | C12: =(A12-1)*설정값!$B$25 -> 700 | D12: =$C$3+(A12-1)*$F$3 -> 1150 | E12: 1 | G12: =설정값!$B$14 -> 25 | H12: =ROUND(G12*(1-설정값!$B$5),0) -> 15 | I12: =-ROUND(설정값!$B$15*E12,0) -> -20 | J12: =-ROUND(설정값!$B$15*E12*(1-설정값!$B$5),0) -> -12 | K12: =IF(A12>=설정값!$B$7,"없음","있음") -> 있음 | L12: =INDEX($B$5:$B$20,MAX(1,A12-설정값!$B$23)) -> 실버 III
A13: 9 | B13: 골드 I | C13: =(A13-1)*설정값!$B$25 -> 800 | D13: =$C$3+(A13-1)*$F$3 -> 1200 | E13: 1 | G13: =설정값!$B$14 -> 25 | H13: =ROUND(G13*(1-설정값!$B$5),0) -> 15 | I13: =-ROUND(설정값!$B$15*E13,0) -> -20 | J13: =-ROUND(설정값!$B$15*E13*(1-설정값!$B$5),0) -> -12 | K13: =IF(A13>=설정값!$B$7,"없음","있음") -> 있음 | L13: =INDEX($B$5:$B$20,MAX(1,A13-설정값!$B$23)) -> 실버 II
A14: 10 | B14: 플래티넘 III | C14: =(A14-1)*설정값!$B$25 -> 900 | D14: =$C$3+(A14-1)*$F$3 -> 1250 | E14: 1 | G14: =설정값!$B$14 -> 25 | H14: =ROUND(G14*(1-설정값!$B$5),0) -> 15 | I14: =-ROUND(설정값!$B$15*E14,0) -> -20 | J14: =-ROUND(설정값!$B$15*E14*(1-설정값!$B$5),0) -> -12 | K14: =IF(A14>=설정값!$B$7,"없음","있음") -> 있음 | L14: =INDEX($B$5:$B$20,MAX(1,A14-설정값!$B$23)) -> 실버 I
A15: 11 | B15: 플래티넘 II | C15: =(A15-1)*설정값!$B$25 -> 1000 | D15: =$C$3+(A15-1)*$F$3 -> 1300 | E15: 1 | G15: =설정값!$B$14 -> 25 | H15: =ROUND(G15*(1-설정값!$B$5),0) -> 15 | I15: =-ROUND(설정값!$B$15*E15,0) -> -20 | J15: =-ROUND(설정값!$B$15*E15*(1-설정값!$B$5),0) -> -12 | K15: =IF(A15>=설정값!$B$7,"없음","있음") -> 있음 | L15: =INDEX($B$5:$B$20,MAX(1,A15-설정값!$B$23)) -> 골드 III
A16: 12 | B16: 플래티넘 I | C16: =(A16-1)*설정값!$B$25 -> 1100 | D16: =$C$3+(A16-1)*$F$3 -> 1350 | E16: 1 | G16: =설정값!$B$14 -> 25 | H16: =ROUND(G16*(1-설정값!$B$5),0) -> 15 | I16: =-ROUND(설정값!$B$15*E16,0) -> -20 | J16: =-ROUND(설정값!$B$15*E16*(1-설정값!$B$5),0) -> -12 | K16: =IF(A16>=설정값!$B$7,"없음","있음") -> 있음 | L16: =INDEX($B$5:$B$20,MAX(1,A16-설정값!$B$23)) -> 골드 II
A17: 13 | B17: 다이아 III | C17: =(A17-1)*설정값!$B$25 -> 1200 | D17: =$C$3+(A17-1)*$F$3 -> 1400 | E17: 1 | F17: 하한선 | G17: =설정값!$B$14 -> 25 | H17: =ROUND(G17*(1-설정값!$B$5),0) -> 15 | I17: =-ROUND(설정값!$B$15*E17,0) -> -20 | J17: =-ROUND(설정값!$B$15*E17*(1-설정값!$B$5),0) -> -12 | K17: =IF(A17>=설정값!$B$7,"없음","있음") -> 없음 | L17: =INDEX($B$5:$B$20,MAX(1,A17-설정값!$B$23)) -> 골드 I
A18: 14 | B18: 다이아 II | C18: =(A18-1)*설정값!$B$25 -> 1300 | D18: =$C$3+(A18-1)*$F$3 -> 1450 | E18: 1 | G18: =설정값!$B$14 -> 25 | H18: =ROUND(G18*(1-설정값!$B$5),0) -> 15 | I18: =-ROUND(설정값!$B$15*E18,0) -> -20 | J18: =-ROUND(설정값!$B$15*E18*(1-설정값!$B$5),0) -> -12 | K18: =IF(A18>=설정값!$B$7,"없음","있음") -> 없음 | L18: =INDEX($B$5:$B$20,MAX(1,A18-설정값!$B$23)) -> 플래티넘 III
A19: 15 | B19: 다이아 I | C19: =(A19-1)*설정값!$B$25 -> 1400 | D19: =$C$3+(A19-1)*$F$3 -> 1500 | E19: 1 | G19: =설정값!$B$14 -> 25 | H19: =ROUND(G19*(1-설정값!$B$5),0) -> 15 | I19: =-ROUND(설정값!$B$15*E19,0) -> -20 | J19: =-ROUND(설정값!$B$15*E19*(1-설정값!$B$5),0) -> -12 | K19: =IF(A19>=설정값!$B$7,"없음","있음") -> 없음 | L19: =INDEX($B$5:$B$20,MAX(1,A19-설정값!$B$23)) -> 플래티넘 II
A20: 16 | B20: 마스터 | C20: =(A20-1)*설정값!$B$25 -> 1500 | D20: =$C$3+(A20-1)*$F$3 -> 1550 | E20: 1 | G20: =설정값!$B$14 -> 25 | H20: =ROUND(G20*(1-설정값!$B$5),0) -> 15 | I20: =-ROUND(설정값!$B$15*E20,0) -> -20 | J20: =-ROUND(설정값!$B$15*E20*(1-설정값!$B$5),0) -> -12 | K20: =IF(A20>=설정값!$B$7,"없음","있음") -> 없음 | L20: =INDEX($B$5:$B$20,MAX(1,A20-설정값!$B$23)) -> 플래티넘 I
A21: 레전드 = 마스터 중 시즌 RP 상위 N%(기본 10%), 인원 상한 100명(별도 순위, 백오피스에서 조정). 표의 RP는 MMR 보정·연승 보너스 0 기준.
A23: RP 계산기 (한 판 결과)
A24: 현재 단계 | C24: 골드 II
A25: 내 숨은 MMR | C25: 1100
A26: 현재 연승 수(이번 판 전) | C26: 2
A27: AI 랭킹전? | C27: 아니오
A28: 시즌 초반 배율 적용? | C28: 아니오
A29: 오늘 AI 랭킹전 판수(이번 판 전) | C29: 0
A31: 단계 기준 MMR | C31: =INDEX($D$5:$D$20,MATCH($C$24,$B$5:$B$20,0)) -> 1150
A32: MMR 보정(RP) | C32: =MAX(-설정값!$B$16,MIN(설정값!$B$16,ROUND(($C$25-INDEX($D$5:$D$20,MATCH($C$24,$B$5:$B$20,0)))/설정값!$B$17,0))) -> -3
A33: 연승 보너스(이번 판 이기면) | C33: =MIN(설정값!$B$20,MAX(0,($C$26+1-설정값!$B$18+1)*설정값!$B$19)) -> 5
A34: AI 배율 | C34: =IF($C$27="예",IF($C$29>=설정값!$B$6,0,1-설정값!$B$5),1) -> 1
A35: 승리 시 RP | C35: =ROUND((설정값!$B$14+C32+C33)*IF($C$28="예",설정값!$B$24,1)*C34,0) -> 27
A36: 패배 시 RP | C36: =-ROUND(MAX(0,설정값!$B$15-C32)*INDEX($E$5:$E$20,MATCH($C$24,$B$5:$B$20,0))*C34,0) -> -23
A37: 이탈 시 RP | C37: =C36-설정값!$B$21 -> -33

Sheet 랭크보상
A1: 랭크를 올리는 이유: 티어별 보상·혜택
A2: 시즌 보상은 '최고 도달 티어' 기준. 수량은 경제 설계 전 가정값.
A3: 일일 첫 승 기본 골드 | C3: 100
A4: 티어 | B4: 시즌 골드 | C4: 시즌 한정 카드 프레임 | D4: 칭호 | E4: 일일 첫 승 배율 | F4: 일일 첫 승 골드 | G4: 프레임 연출 등급 | H4: 주말 챔피언스 컵 | I4: 신캐 선체험 | J4: 시즌 이벤트 스킨
A5: 브론즈 | B5: 500 | E5: 1 | F5: =ROUND($C$3*E5,0) -> 100 | G5: - | H5: 불가 | I5: 불가 | J5: -
A6: 실버 | B6: 1000 | C6: 실버 프레임 | E6: 1.1 | F6: =ROUND($C$3*E6,0) -> 110 | G6: 0 | H6: 불가 | I6: 불가 | J6: -
A7: 골드 | B7: 2000 | C7: 골드 프레임 | E7: 1.2 | F7: =ROUND($C$3*E7,0) -> 120 | G7: 1 메탈 테두리 | H7: 불가 | I7: 불가 | J7: -
A8: 플래티넘 | B8: 3500 | C8: 플래티넘 프레임 | D8: 시즌 칭호 | E8: 1.3 | F8: =ROUND($C$3*E8,0) -> 130 | G8: 1 메탈 테두리 | H8: 가능 | I8: 불가 | J8: 지급
A9: 다이아 | B9: 5000 | C9: 다이아 프레임 | D9: 시즌 칭호 | E9: 1.4 | F9: =ROUND($C$3*E9,0) -> 140 | G9: 2 리버스 홀로 | H9: 가능 | I9: 가능 | J9: 지급
A10: 마스터 | B10: 8000 | C10: 마스터 프레임 | D10: 시즌 칭호 | E10: 1.5 | F10: =ROUND($C$3*E10,0) -> 150 | G10: 3 풀 홀로 | H10: 가능 | I10: 가능 | J10: 지급
A11: 레전드 | B11: 12000 | C11: 레전드 프레임 | D11: 레전드 칭호 + 명예의 전당 | E11: 1.5 | F11: =ROUND($C$3*E11,0) -> 150 | G11: 4 입체 시차 + 닉네임 색 | H11: 가능 | I11: 가능 | J11: 지급
A13: 합계(브론즈→레전드 누적 시즌 골드, 참고) | B13: =SUM(B5:B11) -> 32000
A15: 랭크 로드 1회 보상(각 단계 첫 도달)은 시즌마다 갱신(골드·감정표현·카드 뒷면). 시즌 패스는 없다(2026-10-23). 프레임 연출 등급은 상세 08과 같다.

Sheet 이탈패널티
A1: 이탈 패널티 단계
A2: 최근 N일 누적 이탈 횟수 기준. 정상 완료 M판마다 누적 1회 감면.
A3: 누적 집계 기간(일) | C3: 7
A4: 감면에 필요한 정상 완료 판수 | C4: 5
A5: 네트워크 면책(하루 횟수) | C5: 1
A6: 재접속 유예(초) | C6: =설정값!$B$29 -> 60
A7: AFK 판정 연속 무행동 턴 | C7: 3
A9: 누적 이탈 | B9: 제재 | C9: 매칭 전 대기(분) | D9: 적용 판수 | E9: 판 보상 배율 | F9: 랭킹전 잠금(시간) | G9: 누적 0까지 필요한 정상 판수
A10: 1 | B10: 경고 팝업 | C10: 0 | D10: 0 | E10: 1 | F10: 0 | G10: =A10*$C$4 -> 5
A11: 2 | B11: 매칭 지연 | C11: 5 | D11: 3 | E11: 1 | F11: 0 | G11: =A11*$C$4 -> 10
A12: 3 | B12: 매칭 지연 + 보상 감소 | C12: 15 | D12: 5 | E12: 0.5 | F12: 0 | G12: =A12*$C$4 -> 15
A13: 4 | B13: 랭킹전 잠금 | C13: 0 | D13: 0 | E13: 1 | F13: 24 | G13: =A13*$C$4 -> 20
A14: 5 | B14: 랭킹전 잠금(5회 이상) | C14: 0 | D14: 0 | E14: 1 | F14: 72 | G14: =A14*$C$4 -> 25
A16: 이탈 1회 RP 손실 예시(골드 단계, 보정 0) | C16: =-설정값!$B$15-설정값!$B$21 -> -30
A17: 닷지(밴픽 중 이탈) RP | C17: =-설정값!$B$22 -> -5
A19: 친구 비밀방·AI 대전(연습)은 미적용. AI 랭킹전 이탈은 사람 랭킹전과 같이 누적.

Sheet 에셋
A1: 출시 에셋 수량 (최소화 구조)
A2: 캐릭터 수·스킨 수를 바꾸면 합계가 다시 계산된다. 보이스 제외.
A3: 출시 캐릭터 수 | C3: 9
A4: 출시 스킨 수 | C4: 0
A5: 캐릭터·스킨당 PNG(전신 1 + 얼굴 1) | C5: 2
A7: 분류 | B7: 항목 | C7: 수량 | D7: 비고
A8: 캐릭터 일러스트 | B8: 전신 PNG + 얼굴 크롭컷 | C8: =(C3+C4)*C5 -> 18 | D8: 캐릭터·스킨마다 추가되는 유일한 그림
A9: 카드 키트 | B9: 진영 카드 배경 | C9: 3 | D9: 불·물·바람
A10: 카드 키트 | B10: 중립 카드 배경 | C10: 1 | D10: 공용 전투카드용
A11: 카드 키트 | B11: 등급 테두리 | C11: 4 | D11: 일반·희귀·영웅·전설
A12: 카드 키트 | B12: 카드 종류 아이콘 | C12: 7
A13: 카드 키트 | B13: 전투카드 틀 | C13: 1
A14: 카드 키트 | B14: 카드 뒷면 | C14: 1
A15: 카드 키트 | B15: 스킬 아이콘 프레임 | C15: 2 | D15: 패시브·액티브
A16: 카드 키트 | B16: 상태 오버레이 | C16: 3 | D16: 밴됨·잠긴 스킨·상대 선택
A17: 아이콘 | B17: 상태 아이콘 | C17: 11 | D17: 실드·침묵·면역·약화·공격 강화·작열·표식·손패 봉인·조류·스킬 봉쇄·에너지 감소
A18: 아이콘 | B18: 스펠 아이콘 | C18: 8
A19: 아이콘 | B19: 티어 엠블럼 | C19: 7 | D19: 브론즈~레전드
A20: 아이콘 | B20: 재화 아이콘 | C20: 1 | D20: 골드
A21: UI | B21: 화면 레이아웃 | C21: 10 | D21: 가로 1종
A22: UI | B22: 배경 | C22: 2 | D22: 로비·전투
A23: VFX | B23: 카드 종류별 발동 | C23: 7 | D23: 진영 색 틴트
A24: VFX | B24: 치명·회복·지속 피해 | C24: 3
A25: VFX | B25: 컷인 템플릿·스펠 발동·폭주 진입 | C25: 3
A26: VFX | B26: 승리·패배 | C26: 2
A27: 홀로 키트 | B27: 셰이더 | C27: 1 | D27: 연출 등급 0~4 파라미터
A28: 홀로 키트 | B28: 무지개 색상 텍스처 | C28: 2
A29: 홀로 키트 | B29: 진영 문양 포일 | C29: 3
A30: 홀로 키트 | B30: 스파클 노이즈 | C30: 1
A31: 사운드 | B31: BGM | C31: 3 | D31: 로비·전투·폭주
A32: 사운드 | B32: SFX | C32: 14
A33: 합계 | C33: =SUM(C8:C32) -> 118
A34: 그중 공용 키트(1회 제작) | C34: =C33-C8 -> 100

Sheet 경제
A1: 경제·재화 (골드 1종, 무과금 기준 하루 수입과 외형 획득 속도)
A2: 재화는 골드뿐이고 플레이로만 얻는다(판매 안 함). 파란 글씨는 가정 입력값. 하루 8판·승률 50%·골드 티어 유저 기준.
A3: 항목 | B3: 값 | C3: 단위 | D3: 메모 | E3: 키
A4: 하루 판수(무과금 평균) | B4: 8 | C4: 판 | D4: 랭킹전·AI 대전 합
A5: 승률 | B5: 0.5 | C5: %
A6: 승리 골드 | B6: 30 | C6: 골드/승 | D6: 하루 10승까지 | E6: econ_win_gold
A7: 승리 골드 하루 한도(승) | B7: 10 | C7: 승 | E7: econ_win_daily_cap
A8: 일일 첫 승 기본 골드 | B8: =랭크보상!C3 -> 100 | C8: 골드 | D8: 랭크보상 시트
A9: 기준 티어 첫 승 배율 | B9: =랭크보상!E7 -> 1.2 | C9: 배 | D9: 골드 티어, 랭크보상 시트
A10: 일일 미션 골드(3개 합) | B10: 300 | C10: 골드/일
A11: 주간 미션 골드(5개 합) | B11: 1000 | C11: 골드/주
A12: 출석 골드(7일 합) | B12: 1400 | C12: 골드/주 | E12: econ_attend_week_sum
A13: 출석 7일째 보너스 골드 | B13: 1000 | C13: 골드/주 | E13: econ_attend_day7_bonus
A14: 이벤트·업적 골드 | B14: 2000 | C14: 골드/주 | D14: 가정
A15: 시즌 길이 | B15: 28 | C15: 일 | E15: season_days
A17: 계산 결과
A18: 하루 승리 수 | B18: =MIN($B$4*$B$5,$B$7) -> 4 | C18: 승
A19: 하루 골드 수입 | B19: =$B$10+$B$6*B18+$B$8*$B$9+$B$11/7+$B$12/7+$B$13/7+$B$14/7 -> 1311.4286 | C19: 골드/일
A21: 외형 상품 가격과 무과금 획득 소요일 (가격은 모두 가정, 확정 전)
A22: 상품 | B22: 현금 가격(₩) | C22: 골드 가격 | D22: 무과금 소요일 | E22: 비고
A23: 일반 스킨 | B23: 7900 | C23: 8000 | D23: =C23/$B$19 -> 6.1002179 | E23: 출시 때 골드 판매 0종, 추가 시 캐릭터당 최대 1종
A24: 고급 스킨(홀로 2) | B24: 15900 | C24: - | D24: - | E24: 현금 전용
A25: 한정 스킨(테마 배경+홀로) | B25: 23900 | C25: - | D25: - | E25: 2주 한정, 현금 전용
A26: 홀로 버전 업그레이드 | B26: 7900 | C26: - | D26: - | E26: 보유 스킨, 현금 전용
A27: 카드 뒷면·프레임 | B27: 5900 | C27: 6000 | D27: =C27/$B$19 -> 4.5751634
A28: 감정표현 | B28: 2900 | C28: 3000 | D28: =C28/$B$19 -> 2.2875817 | E28: 기본 4종은 무료
A29: 닉네임 변경(2회째부터) | B29: - | C29: 4000 | D29: =C29/$B$19 -> 3.0501089 | E29: 골드 전용
A31: 번들 할인율 | B31: 0.2 | E31: 스킨 + 카드 뒷면 + 감정표현 묶음
A32: 본편(Steam) 가격(₩) | B32: 19900 | E32: 가정, 출시 직전 확정(총괄 11장)
A33: 신규 캐릭터(출시 후, ₩) | B33: 9900 | E33: 가정, 첫 캐릭터 출시 전 확정. 현금 전용
A34: 누적 28일 출석 보상 | B34: 3000 | C34: 골드/1회 | D34: 누적 출석 28일째 1회만 지급(반복 안 함). 하루 수입 계산에 넣지 않는 장기 보상 | E34: econ_attend_cum28_gold
A35: 시즌 미션 골드(1개) | B35: 500 | C35: 골드/개 | D35: 시즌 미션 10개, 합 5,000/시즌. 하루 수입 계산에 넣지 않는 장기 보상(완주 시 약 +180/일) | E35: econ_season_mission_gold
A36: 연습(AI 대전) 승리 골드 | B36: 15 | C36: 골드/승 | D36: 하루 3판까지만 인정, 일일 첫 승 제외(총괄 8장 "소량") | E36: econ_practice_win_gold
A37: 연습(AI 대전) 하루 인정 판수 | B37: 3 | C37: 판 | D37: 4판째부터 골드·미션 인정 안 함 | E37: econ_practice_daily_games
A38: 골드 상한 999,999, 우편 보관 30일(받은 우편도 30일간 목록에 "받음"으로 표시), 닉네임 첫 변경 무료·이후 4,000, 일일 갱신 05:00·주간 갱신 월요일 05:00(한국 시간)은 문서(상세 05·06)를 따른다.
A40: 미션 표 (상세 05). 범위: ranked = 랭킹전·AI 랭킹전, ranked_ai = 랭킹전·AI 랭킹전 + AI 대전(하루 3판), friend = 친구방, any = 모든 모드
A41: 종류 | B41: ID | C41: 이름 | D41: 조건 종류 | E41: 목표 | F41: 보조값 | G41: 범위 | H41: 골드
A42: 일일 | B42: D01 | C42: 랭킹전 3판 | D42: games | E42: 3 | G42: ranked | H42: 100
A43: 일일 | B43: D02 | C43: 2승 | D43: wins | E43: 2 | G43: ranked_ai | H43: 100
A44: 일일 | B44: D03 | C44: 전용 카드 5장 사용 | D44: signature_cards | E44: 5 | G44: ranked_ai | H44: 100
...

Sheet 추천덱
A1: 추천덱 (캐릭터 9 × 유형 3, 공용 카드 장수)
A2: 파란 숫자 = 공용 카드 장수. 전용 2장은 모든 덱에 고정이라 제외. 합계 10, 같은 카드 최대 2가 아니면 점검 칸이 NG로 바뀐다. 공격 합계(전용 포함)는 공용 공격 장수 + 전용 공격 카드 수이고, 범위는 공세 6~7 · 균형 4~5 · 수비 2~3(상세 15).
A3: 비용(E) | C3: =전투카드!F5 -> 1 | D3: =전투카드!F6 -> 2 | E3: =전투카드!F7 -> 2 | F3: =전투카드!F8 -> 3 | G3: =전투카드!F9 -> 1 | H3: =전투카드!F10 -> 2 | I3: =전투카드!F11 -> 2 | J3: =전투카드!F12 -> 2 | K3: =전투카드!F13 -> 1 | L3: =전투카드!F14 -> 1 | M3: =전투카드!F15 -> 2 | N3: =전투카드!F16 -> 1 | O3: =전투카드!F17 -> 2 | P3: =전투카드!F18 -> 1 | Q3: =전투카드!F19 -> 1 | R3: =전투카드!F20 -> 1
A4: 캐릭터 | B4: 유형 | C4: C01 베기 | D4: C02 강타 | E4: C03 연속 찌르기 | F4: C04 관통 일격 | G4: C05 막기 | H4: C06 철벽 | I4: C07 받아치기 | J4: C08 봉인 | K4: C09 쉿 | L4: C10 정신 집중 | M4: C11 신성 결계 | N4: C12 약화 | O4: C13 응급 처치 | P4: C14 집중 | Q4: C15 전술 드로우 | R4: C16 분노 | S4: 합계 | T4: 평균 비용 | U4: 공격 장수(공용) | V4: 1E 장수 | W4: 점검 | X4: 공격 합계(전용 포함) | Y4: 공격 범위
A5: 아우렐 | B5: 공세 | C5: 2 | D5: 2 | E5: 2 | F5: 0 | G5: 1 | H5: 2 | I5: 0 | J5: 0 | K5: 0 | L5: 0 | M5: 0 | N5: 0 | O5: 0 | P5: 0 | Q5: 0 | R5: 1 | S5: =SUM(C5:R5) -> 10 | T5: =SUMPRODUCT(C5:R5,C$3:R$3)/S5 -> 1.6 | U5: =SUM(C5:F5) -> 6 | V5: =SUMPRODUCT((C$3:R$3=1)*(C5:R5)) -> 4 | W5: =IF(AND(S5=10,MAX(C5:R5)<=2),"OK","NG") -> OK | X5: =U5+COUNTIFS(전투카드!$E$5:$E$40,A5,전투카드!$C$5:$C$40,"공격") -> 6 | Y5: =IF(B5="공세",IF(AND(X5>=6,X5<=7),"OK","NG"),IF(B5="균형",IF(AND(X5>=4,X5<=5),"OK","NG"),IF(AND(X5>=2,X5<=3),"OK","NG"))) -> OK
A6: 아우렐 | B6: 균형 | C6: 2 | D6: 2 | E6: 0 | F6: 0 | G6: 2 | H6: 1 | I6: 1 | J6: 0 | K6: 0 | L6: 1 | M6: 0 | N6: 0 | O6: 0 | P6: 0 | Q6: 1 | R6: 0 | S6: =SUM(C6:R6) -> 10 | T6: =SUMPRODUCT(C6:R6,C$3:R$3)/S6 -> 1.4 | U6: =SUM(C6:F6) -> 4 | V6: =SUMPRODUCT((C$3:R$3=1)*(C6:R6)) -> 6 | W6: =IF(AND(S6=10,MAX(C6:R6)<=2),"OK","NG") -> OK | X6: =U6+COUNTIFS(전투카드!$E$5:$E$40,A6,전투카드!$C$5:$C$40,"공격") -> 4 | Y6: =IF(B6="공세",IF(AND(X6>=6,X6<=7),"OK","NG"),IF(B6="균형",IF(AND(X6>=4,X6<=5),"OK","NG"),IF(AND(X6>=2,X6<=3),"OK","NG"))) -> OK
A7: 아우렐 | B7: 수비 | C7: 2 | D7: 0 | E7: 0 | F7: 0 | G7: 2 | H7: 2 | I7: 1 | J7: 0 | K7: 0 | L7: 1 | M7: 1 | N7: 0 | O7: 0 | P7: 0 | Q7: 1 | R7: 0 | S7: =SUM(C7:R7) -> 10 | T7: =SUMPRODUCT(C7:R7,C$3:R$3)/S7 -> 1.4 | U7: =SUM(C7:F7) -> 2 | V7: =SUMPRODUCT((C$3:R$3=1)*(C7:R7)) -> 6 | W7: =IF(AND(S7=10,MAX(C7:R7)<=2),"OK","NG") -> OK | X7: =U7+COUNTIFS(전투카드!$E$5:$E$40,A7,전투카드!$C$5:$C$40,"공격") -> 2 | Y7: =IF(B7="공세",IF(AND(X7>=6,X7<=7),"OK","NG"),IF(B7="균형",IF(AND(X7>=4,X7<=5),"OK","NG"),IF(AND(X7>=2,X7<=3),"OK","NG"))) -> OK
A8: 피로스 | B8: 공세 | C8: 2 | D8: 2 | E8: 1 | F8: 0 | G8: 0 | H8: 0 | I8: 0 | J8: 0 | K8: 0 | L8: 0 | M8: 0 | N8: 0 | O8: 1 | P8: 1 | Q8: 1 | R8: 2 | S8: =SUM(C8:R8) -> 10 | T8: =SUMPRODUCT(C8:R8,C$3:R$3)/S8 -> 1.4 | U8: =SUM(C8:F8) -> 5 | V8: =SUMPRODUCT((C$3:R$3=1)*(C8:R8)) -> 6 | W8: =IF(AND(S8=10,MAX(C8:R8)<=2),"OK","NG") -> OK | X8: =U8+COUNTIFS(전투카드!$E$5:$E$40,A8,전투카드!$C$5:$C$40,"공격") -> 6 | Y8: =IF(B8="공세",IF(AND(X8>=6,X8<=7),"OK","NG"),IF(B8="균형",IF(AND(X8>=4,X8<=5),"OK","NG"),IF(AND(X8>=2,X8<=3),"OK","NG"))) -> OK
A9: 피로스 | B9: 균형 | C9: 1 | D9: 2 | E9: 0 | F9: 1 | G9: 1 | H9: 0 | I9: 1 | J9: 0 | K9: 0 | L9: 0 | M9: 0 | N9: 0 | O9: 2 | P9: 0 | Q9: 1 | R9: 1 | S9: =SUM(C9:R9) -> 10 | T9: =SUMPRODUCT(C9:R9,C$3:R$3)/S9 -> 1.7 | U9: =SUM(C9:F9) -> 4 | V9: =SUMPRODUCT((C$3:R$3=1)*(C9:R9)) -> 4 | W9: =IF(AND(S9=10,MAX(C9:R9)<=2),"OK","NG") -> OK | X9: =U9+COUNTIFS(전투카드!$E$5:$E$40,A9,전투카드!$C$5:$C$40,"공격") -> 5 | Y9: =IF(B9="공세",IF(AND(X9>=6,X9<=7),"OK","NG"),IF(B9="균형",IF(AND(X9>=4,X9<=5),"OK","NG"),IF(AND(X9>=2,X9<=3),"OK","NG"))) -> OK
A10: 피로스 | B10: 수비 | C10: 1 | D10: 1 | E10: 0 | F10: 0 | G10: 2 | H10: 1 | I10: 1 | J10: 0 | K10: 0 | L10: 0 | M10: 1 | N10: 0 | O10: 2 | P10: 0 | Q10: 1 | R10: 0 | S10: =SUM(C10:R10) -> 10 | T10: =SUMPRODUCT(C10:R10,C$3:R$3)/S10 -> 1.6 | U10: =SUM(C10:F10) -> 2 | V10: =SUMPRODUCT((C$3:R$3=1)*(C10:R10)) -> 4 | W10: =IF(AND(S10=10,MAX(C10:R10)<=2),"OK","NG") -> OK | X10: =U10+COUNTIFS(전투카드!$E$5:$E$40,A10,전투카드!$C$5:$C$40,"공격") -> 3 | Y10: =IF(B10="공세",IF(AND(X10>=6,X10<=7),"OK","NG"),IF(B10="균형",IF(AND(X10>=4,X10<=5),"OK","NG"),IF(AND(X10>=2,X10<=3),"OK","NG"))) -> OK
A11: 이그니스 | B11: 공세 | C11: 2 | D11: 1 | E11: 2 | F11: 0 | G11: 0 | H11: 0 | I11: 0 | J11: 0 | K11: 0 | L11: 1 | M11: 0 | N11: 1 | O11: 0 | P11: 1 | Q11: 1 | R11: 1 | S11: =SUM(C11:R11) -> 10 | T11: =SUMPRODUCT(C11:R11,C$3:R$3)/S11 -> 1.3 | U11: =SUM(C11:F11) -> 5 | V11: =SUMPRODUCT((C$3:R$3=1)*(C11:R11)) -> 7 | W11: =IF(AND(S11=10,MAX(C11:R11)<=2),"OK","NG") -> OK | X11: =U11+COUNTIFS(전투카드!$E$5:$E$40,A11,전투카드!$C$5:$C$40,"공격") -> 6 | Y11: =IF(B11="공세",IF(AND(X11>=6,X11<=7),"OK","NG"),IF(B11="균형",IF(AND(X11>=4,X11<=5),"OK","NG"),IF(AND(X11>=2,X11<=3),"OK","NG"))) -> OK
A12: 이그니스 | B12: 균형 | C12: 1 | D12: 1 | E12: 1 | F12: 0 | G12: 1 | H12: 0 | I12: 1 | J12: 0 | K12: 0 | L12: 1 | M12: 0 | N12: 1 | O12: 1 | P12: 1 | Q12: 1 | R12: 0 | S12: =SUM(C12:R12) -> 10 | T12: =SUMPRODUCT(C12:R12,C$3:R$3)/S12 -> 1.4 | U12: =SUM(C12:F12) -> 3 | V12: =SUMPRODUCT((C$3:R$3=1)*(C12:R12)) -> 6 | W12: =IF(AND(S12=10,MAX(C12:R12)<=2),"OK","NG") -> OK | X12: =U12+COUNTIFS(전투카드!$E$5:$E$40,A12,전투카드!$C$5:$C$40,"공격") -> 4 | Y12: =IF(B12="공세",IF(AND(X12>=6,X12<=7),"OK","NG"),IF(B12="균형",IF(AND(X12>=4,X12<=5),"OK","NG"),IF(AND(X12>=2,X12<=3),"OK","NG"))) -> OK
A13: 이그니스 | B13: 수비 | C13: 0 | D13: 0 | E13: 1 | F13: 0 | G13: 2 | H13: 1 | I13: 1 | J13: 0 | K13: 0 | L13: 2 | M13: 1 | N13: 0 | O13: 1 | P13: 0 | Q13: 1 | R13: 0 | S13: =SUM(C13:R13) -> 10 | T13: =SUMPRODUCT(C13:R13,C$3:R$3)/S13 -> 1.5 | U13: =SUM(C13:F13) -> 1 | V13: =SUMPRODUCT((C$3:R$3=1)*(C13:R13)) -> 5 | W13: =IF(AND(S13=10,MAX(C13:R13)<=2),"OK","NG") -> OK | X13: =U13+COUNTIFS(전투카드!$E$5:$E$40,A13,전투카드!$C$5:$C$40,"공격") -> 2 | Y13: =IF(B13="공세",IF(AND(X13>=6,X13<=7),"OK","NG"),IF(B13="균형",IF(AND(X13>=4,X13<=5),"OK","NG"),IF(AND(X13>=2,X13<=3),"OK","NG"))) -> OK
A14: 셀레네 | B14: 공세 | C14: 2 | D14: 2 | E14: 1 | F14: 0 | G14: 1 | H14: 0 | I14: 0 | J14: 0 | K14: 0 | L14: 0 | M14: 0 | N14: 0 | O14: 0 | P14: 1 | Q14: 1 | R14: 2 | S14: =SUM(C14:R14) -> 10 | T14: =SUMPRODUCT(C14:R14,C$3:R$3)/S14 -> 1.3 | U14: =SUM(C14:F14) -> 5 | V14: =SUMPRODUCT((C$3:R$3=1)*(C14:R14)) -> 7 | W14: =IF(AND(S14=10,MAX(C14:R14)<=2),"OK","NG") -> OK | X14: =U14+COUNTIFS(전투카드!$E$5:$E$40,A14,전투카드!$C$5:$C$40,"공격") -> 6 | Y14: =IF(B14="공세",IF(AND(X14>=6,X14<=7),"OK","NG"),IF(B14="균형",IF(AND(X14>=4,X14<=5),"OK","NG"),IF(AND(X14>=2,X14<=3),"OK","NG"))) -> OK
A15: 셀레네 | B15: 균형 | C15: 2 | D15: 1 | E15: 0 | F15: 0 | G15: 2 | H15: 0 | I15: 1 | J15: 0 | K15: 0 | L15: 1 | M15: 0 | N15: 0 | O15: 1 | P15: 1 | Q15: 1 | R15: 0 | S15: =SUM(C15:R15) -> 10 | T15: =SUMPRODUCT(C15:R15,C$3:R$3)/S15 -> 1.3 | U15: =SUM(C15:F15) -> 3 | V15: =SUMPRODUCT((C$3:R$3=1)*(C15:R15)) -> 7 | W15: =IF(AND(S15=10,MAX(C15:R15)<=2),"OK","NG") -> OK | X15: =U15+COUNTIFS(전투카드!$E$5:$E$40,A15,전투카드!$C$5:$C$40,"공격") -> 4 | Y15: =IF(B15="공세",IF(AND(X15>=6,X15<=7),"OK","NG"),IF(B15="균형",IF(AND(X15>=4,X15<=5),"OK","NG"),IF(AND(X15>=2,X15<=3),"OK","NG"))) -> OK
A16: 셀레네 | B16: 수비 | C16: 1 | D16: 0 | E16: 0 | F16: 0 | G16: 2 | H16: 2 | I16: 1 | J16: 0 | K16: 0 | L16: 1 | M16: 1 | N16: 0 | O16: 1 | P16: 0 | Q16: 1 | R16: 0 | S16: =SUM(C16:R16) -> 10 | T16: =SUMPRODUCT(C16:R16,C$3:R$3)/S16 -> 1.5 | U16: =SUM(C16:F16) -> 1 | V16: =SUMPRODUCT((C$3:R$3=1)*(C16:R16)) -> 5 | W16: =IF(AND(S16=10,MAX(C16:R16)<=2),"OK","NG") -> OK | X16: =U16+COUNTIFS(전투카드!$E$5:$E$40,A16,전투카드!$C$5:$C$40,"공격") -> 2 | Y16: =IF(B16="공세",IF(AND(X16>=6,X16<=7),"OK","NG"),IF(B16="균형",IF(AND(X16>=4,X16<=5),"OK","NG"),IF(AND(X16>=2,X16<=3),"OK","NG"))) -> OK
